Workbook
Name CategoryList: Settings!$A$4:$A$11
Name DepartmentList: Settings!$C$4:$C$11
Name ItemCategoryLookup: 'Inventory-Master'!$B$3:$C$32
Name ItemFullTable: 'Inventory-Master'!$A$3:$L$32
Name ItemList: 'Inventory-Master'!$B$3:$B$32
Name MovementTypeList: Settings!$H$4:$H$7
Name POStatusList: Settings!$E$4:$E$8
Name PriorityList: Settings!$F$4:$F$7
Name ReqStatusList: Settings!$D$4:$D$7
Name SupplierList: Suppliers!$B$3:$B$12
Name SupplierStatusList: Settings!$G$4:$G$5
Name UnitList: Settings!$B$4:$B$8

Sheet Dashboard
A1: Sample Office Supply Inventory & Procurement Monitoring System
N2: Chart Support Data (auto-calculated — do not delete)
N3: Paper Products | O3: =SUMIF('Inventory-Master'!$C$3:$C$32,N3,'Inventory-Master'!$H$3:$H$32) -> 5800
A4: TOTAL ITEMS | C4: INVENTORY VALUE | E4: LOW STOCK ITEMS | G4: PENDING REQUESTS | I4: ACTIVE SUPPLIERS | K4: MONTHLY PROCUREMENT COST | N4: Writing Instruments | O4: =SUMIF('Inventory-Master'!$C$3:$C$32,N4,'Inventory-Master'!$H$3:$H$32) -> 8355
A5: =COUNTA('Inventory-Master'!B3:B32) -> 30 | C5: =SUM('Inventory-Master'!H3:H32) -> 74930 | E5: =COUNTIF('Inventory-Master'!J3:J32,"Low Stock") -> 4 | G5: =COUNTIF('Procurement-Requests'!I3:I32,"Pending") -> 8 | I5: =COUNTIF(Suppliers!G3:G12,"Active") -> 9 | K5: =INDEX('Monthly-Report'!F3:F8,MATCH(MAX('Monthly-Report'!A3:A8),'Monthly-Report'!A3:A8,0)) -> 5950 | N5: Office Equipment | O5: =SUMIF('Inventory-Master'!$C$3:$C$32,N5,'Inventory-Master'!$H$3:$H$32) -> 14750
N6: Filing & Storage | O6: =SUMIF('Inventory-Master'!$C$3:$C$32,N6,'Inventory-Master'!$H$3:$H$32) -> 17300 | P6: =IF('Inventory-Master'!J7="Low Stock",ROW('Inventory-Master'!J7),"")
N7: Stationery | O7: =SUMIF('Inventory-Master'!$C$3:$C$32,N7,'Inventory-Master'!$H$3:$H$32) -> 1425 | P7: =IF('Inventory-Master'!J8="Low Stock",ROW('Inventory-Master'!J8),"")
N8: Printing Supplies | O8: =SUMIF('Inventory-Master'!$C$3:$C$32,N8,'Inventory-Master'!$H$3:$H$32) -> 18500 | P8: =IF('Inventory-Master'!J9="Low Stock",ROW('Inventory-Master'!J9),"")
A9: Category | B9: Inventory Table | H9: Department | I9: Requests | N9: IT Accessories | O9: =SUMIF('Inventory-Master'!$C$3:$C$32,N9,'Inventory-Master'!$H$3:$H$32) -> 6000 | P9: =IF('Inventory-Master'!J10="Low Stock",ROW('Inventory-Master'!J10),"")
A10: Writing Instruments | B10: =SUMIF('Inventory-Master'!C2:C32,A10,'Inventory-Master'!H3:H32) -> 7855 | H10: Finance | I10: =COUNTIF('Procurement-Requests'!C2:C32,H10) -> 9 | N10: Packaging Materials | O10: =SUMIF('Inventory-Master'!$C$3:$C$32,N10,'Inventory-Master'!$H$3:$H$32) -> 2800 | P10: =IF('Inventory-Master'!J11="Low Stock",ROW('Inventory-Master'!J11),"")
A11: Office Equipment | B11: =SUMIF('Inventory-Master'!C3:C33,A11,'Inventory-Master'!H4:H33) -> 13650 | H11: Admin | I11: =COUNTIF('Procurement-Requests'!C3:C33,H11) -> 4 | P11: =IF('Inventory-Master'!J12="Low Stock",ROW('Inventory-Master'!J12),"")
A12: Filing & Storage | B12: =SUMIF('Inventory-Master'!C4:C34,A12,'Inventory-Master'!H5:H34) -> 18000 | H12: Marketing | I12: =COUNTIF('Procurement-Requests'!C4:C34,H12) -> 4 | N12: PO Status | O12: Count | P12: =IF('Inventory-Master'!J13="Low Stock",ROW('Inventory-Master'!J13),"")
A13: Paper Products | B13: =SUMIF('Inventory-Master'!C5:C35,A13,'Inventory-Master'!H6:H35) -> 1050 | H13: IT | I13: =COUNTIF('Procurement-Requests'!C5:C35,H13) -> 3 | N13: Pending | O13: =COUNTIF('Purchase-Orders'!$J$3:$J$30,N13) -> 3 | P13: =IF('Inventory-Master'!J14="Low Stock",ROW('Inventory-Master'!J14),"")
A14: Stationery | B14: =SUMIF('Inventory-Master'!C6:C36,A14,'Inventory-Master'!H7:H36) -> 1175 | H14: HR | I14: =COUNTIF('Procurement-Requests'!C6:C36,H14) -> 4 | N14: Ordered | O14: =COUNTIF('Purchase-Orders'!$J$3:$J$30,N14) -> 6 | P14: =IF('Inventory-Master'!J15="Low Stock",ROW('Inventory-Master'!J15),"")
A15: Printing Supplies | B15: =SUMIF('Inventory-Master'!C7:C37,A15,'Inventory-Master'!H8:H37) -> 23700 | H15: Operations | I15: =COUNTIF('Procurement-Requests'!C7:C37,H15) -> 2 | N15: Partially Delivered | O15: =COUNTIF('Purchase-Orders'!$J$3:$J$30,N15) -> 1 | P15: =IF('Inventory-Master'!J16="Low Stock",ROW('Inventory-Master'!J16),"")
A16: IT Accessories | B16: =SUMIF('Inventory-Master'!C8:C38,A16,'Inventory-Master'!H9:H38) -> 1000 | H16: Sales | I16: =COUNTIF('Procurement-Requests'!C8:C38,H16) -> 2 | N16: Delivered | O16: =COUNTIF('Purchase-Orders'!$J$3:$J$30,N16) -> 17 | P16: =IF('Inventory-Master'!J17="Low Stock",ROW('Inventory-Master'!J17),"")
A17: Packaging Materials | B17: =SUMIF('Inventory-Master'!C9:C39,A17,'Inventory-Master'!H10:H39) -> 5800 | H17: Procurement | I17: =COUNTIF('Procurement-Requests'!C9:C39,H17) -> 2 | N17: Cancelled | O17: =COUNTIF('Purchase-Orders'!$J$3:$J$30,N17) -> 1 | P17: =IF('Inventory-Master'!J18="Low Stock",ROW('Inventory-Master'!J18),"")
P18: =IF('Inventory-Master'!J19="Low Stock",ROW('Inventory-Master'!J19),"")
N19: Department | O19: Requests | P19: =IF('Inventory-Master'!J20="Low Stock",ROW('Inventory-Master'!J20),"")
N20: Admin | O20: =COUNTIF('Procurement-Requests'!$C$3:$C$32,N20) -> 4 | P20: =IF('Inventory-Master'!J21="Low Stock",ROW('Inventory-Master'!J21),"")
N21: Finance | O21: =COUNTIF('Procurement-Requests'!$C$3:$C$32,N21) -> 9 | P21: =IF('Inventory-Master'!J22="Low Stock",ROW('Inventory-Master'!J22),"")
N22: HR | O22: =COUNTIF('Procurement-Requests'!$C$3:$C$32,N22) -> 4
N23: IT | O23: =COUNTIF('Procurement-Requests'!$C$3:$C$32,N23) -> 3 | P23: =IF('Inventory-Master'!J24="Low Stock",ROW('Inventory-Master'!J24),"")
N24: Marketing | O24: =COUNTIF('Procurement-Requests'!$C$3:$C$32,N24) -> 4 | P24: =IF('Inventory-Master'!J25="Low Stock",ROW('Inventory-Master'!J25),"")
A25: Status | B25: Count | N25: Operations | O25: =COUNTIF('Procurement-Requests'!$C$3:$C$32,N25) -> 2 | P25: =IF('Inventory-Master'!J26="Low Stock",ROW('Inventory-Master'!J26),"")
A26: Delivered | B26: =COUNTIF('Purchase-Orders'!J2:J30,A26) -> 17 | N26: Procurement | O26: =COUNTIF('Procurement-Requests'!$C$3:$C$32,N26) -> 2 | P26: =IF('Inventory-Master'!J27="Low Stock",ROW('Inventory-Master'!J27),"")
A27: Ordered | B27: =COUNTIF('Purchase-Orders'!J3:J31,A27) -> 6 | N27: Sales | O27: =COUNTIF('Procurement-Requests'!$C$3:$C$32,N27) -> 2
A28: Pending | B28: =COUNTIF('Purchase-Orders'!J4:J32,A28) -> 3 | P28: =IF('Inventory-Master'!J29="Low Stock",ROW('Inventory-Master'!J29),"")
A29: Partially Delivered | B29: =COUNTIF('Purchase-Orders'!J5:J33,A29) -> 1 | P29: =IF('Inventory-Master'!J30="Low Stock",ROW('Inventory-Master'!J30),"")
A30: Cancelled | B30: =COUNTIF('Purchase-Orders'!J6:J34,A30) -> 1 | P30: =IF('Inventory-Master'!J31="Low Stock",ROW('Inventory-Master'!J31),"")
H35: Month | I35: Sum of Total Procurement Spend
H36: 46023 | I36: 14000
H37: 46054 | I37: 8690
H38: 46082 | I38: 34175
H39: 46113 | I39: 181175
H40: 46143 | I40: 6375
H41: 46174 | I41: 5950
H42: Grand Total | I42: 250365
A44: ⚠ Low Stock Alert — Items Requiring Immediate Reorder
A45: Item ID | B45: Item Name | C45: Category | D45: Current Stock | E45: Reorder Level | F45: Suggested Reorder Qty
...

Sheet Inventory-Master
A1: Inventory Master List
A2: Item ID | B2: Item Name | C2: Category | D2: Unit | E2: Reorder Level | F2: Current Stock | G2: Unit Cost | H2: Stock Value | I2: Reorder Qty Suggested | J2: Stock Status | K2: Preferred Supplier | L2: Last Restocked
A3: ITM-001 | B3: Bond Paper A4 | C3: Paper Products | D3: Ream | E3: 5 | F3: 10 | G3: 130 | H3: =F3*G3 -> 1300 | I3: =IF(F3<=E3,(E3*2)-F3,0) -> 0 | J3: =IF(F3<=E3,"Low Stock",IF(F3<=E3*1.5,"Monitor","OK")) -> OK | K3: Prime Paper Solutions | L3: 46086
A4: ITM-002 | B4: Ballpen Black | C4: Writing Instruments | D4: Box | E4: 10 | F4: 20 | G4: 70 | H4: =F4*G4 -> 1400 | I4: =IF(F4<=E4,(E4*2)-F4,0) -> 0 | J4: =IF(F4<=E4,"Low Stock",IF(F4<=E4*1.5,"Monitor","OK")) -> OK | K4: Signature Pens & More | L4: 46133
A5: ITM-003 | B5: Stapler | C5: Office Equipment | D5: Piece | E5: 30 | F5: 30 | G5: 35 | H5: =F5*G5 -> 1050 | I5: =IF(F5<=E5,(E5*2)-F5,0) -> 30 | J5: =IF(F5<=E5,"Low Stock",IF(F5<=E5*1.5,"Monitor","OK")) -> Low Stock | K5: Office Essentials Trading | L5: 46025
A6: ITM-004 | B6: Staple Wire | C6: Office Equipment | D6: Box | E6: 30 | F6: 90 | G6: 40 | H6: =F6*G6 -> 3600 | I6: =IF(F6<=E6,(E6*2)-F6,0) -> 0 | J6: =IF(F6<=E6,"Low Stock",IF(F6<=E6*1.5,"Monitor","OK")) -> OK | K6: Office Essentials Trading | L6: 46146
A7: ITM-005 | B7: Pencil HB | C7: Writing Instruments | D7: Box | E7: 5 | F7: 15 | G7: 100 | H7: =F7*G7 -> 1500 | I7: =IF(F7<=E7,(E7*2)-F7,0) -> 0 | J7: =IF(F7<=E7,"Low Stock",IF(F7<=E7*1.5,"Monitor","OK")) -> OK | K7: Signature Pens & More | L7: 46100
A8: ITM-006 | B8: Eraser | C8: Writing Instruments | D8: Box | E8: 10 | F8: 20 | G8: 50 | H8: =F8*G8 -> 1000 | I8: =IF(F8<=E8,(E8*2)-F8,0) -> 0 | J8: =IF(F8<=E8,"Low Stock",IF(F8<=E8*1.5,"Monitor","OK")) -> OK | K8: Signature Pens & More | L8: 46039
A9: ITM-007 | B9: Highlighter Yellow | C9: Writing Instruments | D9: Piece | E9: 30 | F9: 60 | G9: 48 | H9: =F9*G9 -> 2880 | I9: =IF(F9<=E9,(E9*2)-F9,0) -> 0 | J9: =IF(F9<=E9,"Low Stock",IF(F9<=E9*1.5,"Monitor","OK")) -> OK | K9: Signature Pens & More | L9: 46055
A10: ITM-008 | B10: Permanent Marker Black | C10: Writing Instruments | D10: Piece | E10: 30 | F10: 50 | G10: 15 | H10: =F10*G10 -> 750 | I10: =IF(F10<=E10,(E10*2)-F10,0) -> 0 | J10: =IF(F10<=E10,"Low Stock",IF(F10<=E10*1.5,"Monitor","OK")) -> OK | K10: Signature Pens & More | L10: 46036
A11: ITM-009 | B11: Whiteboard Marker Blue | C11: Writing Instruments | D11: Piece | E11: 30 | F11: 55 | G11: 15 | H11: =F11*G11 -> 825 | I11: =IF(F11<=E11,(E11*2)-F11,0) -> 0 | J11: =IF(F11<=E11,"Low Stock",IF(F11<=E11*1.5,"Monitor","OK")) -> OK | K11: Signature Pens & More | L11: 46115
A12: ITM-010 | B12: Correction Tape | C12: Office Equipment | D12: Piece | E12: 30 | F12: 90 | G12: 15 | H12: =F12*G12 -> 1350 | I12: =IF(F12<=E12,(E12*2)-F12,0) -> 0 | J12: =IF(F12<=E12,"Low Stock",IF(F12<=E12*1.5,"Monitor","OK")) -> OK | K12: Office Essentials Trading | L12: 46056
A13: ITM-011 | B13: Glue Stick | C13: Office Equipment | D13: Pack | E13: 5 | F13: 15 | G13: 45 | H13: =F13*G13 -> 675 | I13: =IF(F13<=E13,(E13*2)-F13,0) -> 0 | J13: =IF(F13<=E13,"Low Stock",IF(F13<=E13*1.5,"Monitor","OK")) -> OK | K13: Office Essentials Trading | L13: 46156
A14: ITM-012 | B14: Scissors | C14: Office Equipment | D14: Piece | E14: 30 | F14: 40 | G14: 10 | H14: =F14*G14 -> 400 | I14: =IF(F14<=E14,(E14*2)-F14,0) -> 0 | J14: =IF(F14<=E14,"Low Stock",IF(F14<=E14*1.5,"Monitor","OK")) -> Monitor | K14: Office Essentials Trading | L14: 46049
... A32: ITM-030 | B32: Calculator | C32: Office Equipment | D32: Piece | E32: 10 | F32: 10 | G32: 400 | H32: =F32*G32 -> 4000 | I32: =IF(F32<=E32,(E32*2)-F32,0) -> 10 | J32: =IF(F32<=E32,"Low Stock",IF(F32<=E32*1.5,"Monitor","OK")) -> Low Stock | K32: Office Essentials Trading | L32: 46176

Sheet Stock-Issuance
A1: Stock Issuance Log
A2: Issuance ID | B2: Date | C2: Item | D2: Category | E2: Department | F2: Quantity Issued | G2: Unit Cost | H2: Total Value | I2: Issued By | J2: Purpose / Remarks
A3: ISS-0001 | B3: 46030 | C3: Bond Paper A4 | D3: =IFERROR(INDEX('Inventory-Master'!$C$3:$C$32,MATCH(C3,'Inventory-Master'!$B$3:$B$32,0)),"") -> Paper Products | E3: IT | F3: 15 | G3: =IFERROR(INDEX('Inventory-Master'!$G$3:$G$32,MATCH(C3,'Inventory-Master'!$B$3:$B$32,0)),0) -> 130 | H3: =F3*G3 -> 1950 | I3: Lorna Pascual | J3: Event/meeting preparation
A4: ISS-0002 | B4: 46081 | C4: Stapler | D4: =IFERROR(INDEX('Inventory-Master'!$C$3:$C$32,MATCH(C4,'Inventory-Master'!$B$3:$B$32,0)),"") -> Office Equipment | E4: Marketing | F4: 10 | G4: =IFERROR(INDEX('Inventory-Master'!$G$3:$G$32,MATCH(C4,'Inventory-Master'!$B$3:$B$32,0)),0) -> 35 | H4: =F4*G4 -> 350 | I4: Jun Bautista | J4: Replacement of damaged item
A5: ISS-0003 | B5: 46094 | C5: Printer Ink Black | D5: =IFERROR(INDEX('Inventory-Master'!$C$3:$C$32,MATCH(C5,'Inventory-Master'!$B$3:$B$32,0)),"") -> Printing Supplies | E5: Operations | F5: 1 | G5: =IFERROR(INDEX('Inventory-Master'!$G$3:$G$32,MATCH(C5,'Inventory-Master'!$B$3:$B$32,0)),0) -> 100 | H5: =F5*G5 -> 100 | I5: Ferdie Aguilar | J5: Event/meeting preparation
A6: ISS-0004 | B6: 46118 | C6: Notebook A5 | D6: =IFERROR(INDEX('Inventory-Master'!$C$3:$C$32,MATCH(C6,'Inventory-Master'!$B$3:$B$32,0)),"") -> Paper Products | E6: Marketing | F6: 1 | G6: =IFERROR(INDEX('Inventory-Master'!$G$3:$G$32,MATCH(C6,'Inventory-Master'!$B$3:$B$32,0)),0) -> 150 | H6: =F6*G6 -> 150 | I6: Ferdie Aguilar | J6: Replacement of damaged item
A7: ISS-0005 | B7: 46156 | C7: Scissors | D7: =IFERROR(INDEX('Inventory-Master'!$C$3:$C$32,MATCH(C7,'Inventory-Master'!$B$3:$B$32,0)),"") -> Office Equipment | E7: Operations | F7: 15 | G7: =IFERROR(INDEX('Inventory-Master'!$G$3:$G$32,MATCH(C7,'Inventory-Master'!$B$3:$B$32,0)),0) -> 10 | H7: =F7*G7 -> 150 | I7: Jun Bautista | J7: Replacement of damaged item
A8: ISS-0006 | B8: 46177 | C8: Paper Clips | D8: =IFERROR(INDEX('Inventory-Master'!$C$3:$C$32,MATCH(C8,'Inventory-Master'!$B$3:$B$32,0)),"") -> Office Equipment | E8: IT | F8: 8 | G8: =IFERROR(INDEX('Inventory-Master'!$G$3:$G$32,MATCH(C8,'Inventory-Master'!$B$3:$B$32,0)),0) -> 35 | H8: =F8*G8 -> 280 | I8: Ferdie Aguilar | J8: Project-specific requirement
A9: ISS-0007 | B9: 46036 | C9: Bond Paper A4 | D9: =IFERROR(INDEX('Inventory-Master'!$C$3:$C$32,MATCH(C9,'Inventory-Master'!$B$3:$B$32,0)),"") -> Paper Products | E9: IT | F9: 10 | G9: =IFERROR(INDEX('Inventory-Master'!$G$3:$G$32,MATCH(C9,'Inventory-Master'!$B$3:$B$32,0)),0) -> 130 | H9: =F9*G9 -> 1300 | I9: Lorna Pascual | J9: Routine department replenishment
A10: ISS-0008 | B10: 46075 | C10: Calculator | D10: =IFERROR(INDEX('Inventory-Master'!$C$3:$C$32,MATCH(C10,'Inventory-Master'!$B$3:$B$32,0)),"") -> Office Equipment | E10: Operations | F10: 10 | G10: =IFERROR(INDEX('Inventory-Master'!$G$3:$G$32,MATCH(C10,'Inventory-Master'!$B$3:$B$32,0)),0) -> 400 | H10: =F10*G10 -> 4000 | I10: Jun Bautista | J10: Routine department replenishment
A11: ISS-0009 | B11: 46105 | C11: Packaging Tape | D11: =IFERROR(INDEX('Inventory-Master'!$C$3:$C$32,MATCH(C11,'Inventory-Master'!$B$3:$B$32,0)),"") -> Packaging Materials | E11: Marketing | F11: 8 | G11: =IFERROR(INDEX('Inventory-Master'!$G$3:$G$32,MATCH(C11,'Inventory-Master'!$B$3:$B$32,0)),0) -> 40 | H11: =F11*G11 -> 320 | I11: Jun Bautista | J11: Monthly office supply allocation
A12: ISS-0010 | B12: 46123 | C12: Paper Clips | D12: =IFERROR(INDEX('Inventory-Master'!$C$3:$C$32,MATCH(C12,'Inventory-Master'!$B$3:$B$32,0)),"") -> Office Equipment | E12: Marketing | F12: 3 | G12: =IFERROR(INDEX('Inventory-Master'!$G$3:$G$32,MATCH(C12,'Inventory-Master'!$B$3:$B$32,0)),0) -> 35 | H12: =F12*G12 -> 105 | I12: Ferdie Aguilar | J12: Monthly office supply allocation
A13: ISS-0011 | B13: 46164 | C13: Paper Clips | D13: =IFERROR(INDEX('Inventory-Master'!$C$3:$C$32,MATCH(C13,'Inventory-Master'!$B$3:$B$32,0)),"") -> Office Equipment | E13: HR | F13: 8 | G13: =IFERROR(INDEX('Inventory-Master'!$G$3:$G$32,MATCH(C13,'Inventory-Master'!$B$3:$B$32,0)),0) -> 35 | H13: =F13*G13 -> 280 | I13: Lorna Pascual | J13: Replacement of damaged item
A14: ISS-0012 | B14: 46200 | C14: Bond Paper A4 | D14: =IFERROR(INDEX('Inventory-Master'!$C$3:$C$32,MATCH(C14,'Inventory-Master'!$B$3:$B$32,0)),"") -> Paper Products | E14: Marketing | F14: 8 | G14: =IFERROR(INDEX('Inventory-Master'!$G$3:$G$32,MATCH(C14,'Inventory-Master'!$B$3:$B$32,0)),0) -> 130 | H14: =F14*G14 -> 1040 | I14: Ferdie Aguilar | J14: Monthly office supply allocation
... A47: ISS-0045 | B47: 46085 | C47: Notebook A5 | D47: =IFERROR(INDEX('Inventory-Master'!$C$3:$C$32,MATCH(C47,'Inventory-Master'!$B$3:$B$32,0)),"") -> Paper Products | E47: Admin | F47: 8 | G47: =IFERROR(INDEX('Inventory-Master'!$G$3:$G$32,MATCH(C47,'Inventory-Master'!$B$3:$B$32,0)),0) -> 150 | H47: =F47*G47 -> 1200 | I47: Jun Bautista | J47: Project-specific requirement

Sheet Suppliers
A1: Supplier Directory
A2: Supplier ID | B2: Supplier Name | C2: Contact Person | D2: Email | E2: Phone | F2: Category Supplied | G2: Status | H2: Date Onboarded | I2: Total POs | J2: Total Spend | K2: Rating (1-5)
A3: SUP-001 | B3: Prime Paper Solutions | C3: Maria Santos | D3: maria.santos@primepaper.com | E3: 0917 345 2101 | F3: Paper Products | G3: Active | H3: 44999 | I3: =COUNTIF('Purchase-Orders'!$D$3:$D$1000,B3) -> 1 | J3: =SUMIF('Purchase-Orders'!$D$3:$D$1000,B3,'Purchase-Orders'!$I$3:$I$1000) -> 650 | K3: 4.6
A4: SUP-002 | B4: Office Essentials Trading | C4: John Reyes | D4: john.reyes@officeessentials.com | E4: 0918 456 3210 | F4: Office Equipment | G4: Active | H4: 44867 | I4: =COUNTIF('Purchase-Orders'!$D$3:$D$1000,B4) -> 1 | J4: =SUMIF('Purchase-Orders'!$D$3:$D$1000,B4,'Purchase-Orders'!$I$3:$I$1000) -> 300 | K4: 4.3
A5: SUP-003 | B5: PrintTech Supplies Inc. | C5: Anna Cruz | D5: anna.cruz@printtechsupplies.com | E5: 0919 567 4321 | F5: Printing Supplies | G5: Active | H5: 44946 | I5: =COUNTIF('Purchase-Orders'!$D$3:$D$1000,B5) -> 5 | J5: =SUMIF('Purchase-Orders'!$D$3:$D$1000,B5,'Purchase-Orders'!$I$3:$I$1000) -> 11000 | K5: 4.7
A6: SUP-004 | B6: Workspace Equipment Corp. | C6: Michael Garcia | D6: michael.garcia@workspaceequip.com | E6: 0920 678 5432 | F6: Office Equipment | G6: Active | H6: 44386 | I6: =COUNTIF('Purchase-Orders'!$D$3:$D$1000,B6) -> 5 | J6: =SUMIF('Purchase-Orders'!$D$3:$D$1000,B6,'Purchase-Orders'!$I$3:$I$1000) -> 5575 | K6: 4.1
A7: SUP-005 | B7: SecureFile Solutions | C7: Catherine Lopez | D7: c.lopez@securefile.com | E7: 0921 789 6543 | F7: Filing & Storage | G7: Active | H7: 44711 | I7: =COUNTIF('Purchase-Orders'!$D$3:$D$1000,B7) -> 2 | J7: =SUMIF('Purchase-Orders'!$D$3:$D$1000,B7,'Purchase-Orders'!$I$3:$I$1000) -> 12000 | K7: 4.4
A8: SUP-006 | B8: TechLink Accessories | C8: David Mendoza | D8: david.mendoza@techlinkacc.com | E8: 0922 890 7654 | F8: IT Accessories | G8: Active | H8: 45155 | I8: =COUNTIF('Purchase-Orders'!$D$3:$D$1000,B8) -> 1 | J8: =SUMIF('Purchase-Orders'!$D$3:$D$1000,B8,'Purchase-Orders'!$I$3:$I$1000) -> 24000 | K8: 4.2
A9: SUP-007 | B9: Signature Pens & More | C9: Jennifer Ramos | D9: j.ramos@signaturepens.com | E9: 0923 901 8765 | F9: Writing Instruments | G9: Active | H9: 44603 | I9: =COUNTIF('Purchase-Orders'!$D$3:$D$1000,B9) -> 7 | J9: =SUMIF('Purchase-Orders'!$D$3:$D$1000,B9,'Purchase-Orders'!$I$3:$I$1000) -> 9665 | K9: 4.5
A10: SUP-008 | B10: PackRight Enterprises | C10: Robert Villanueva | D10: robert.v@packright.com | E10: 0924 112 9876 | F10: Packaging Materials | G10: Inactive | H10: 44473 | I10: =COUNTIF('Purchase-Orders'!$D$3:$D$1000,B10) -> 0 | J10: =SUMIF('Purchase-Orders'!$D$3:$D$1000,B10,'Purchase-Orders'!$I$3:$I$1000) -> 0 | K10: 3.8
A11: SUP-009 | B11: BizForm Print Co. | C11: Louie Fernandez | D11: louie.f@bizformprint.com | E11: 0925 223 0987 | F11: Printing Supplies | G11: Active | H11: 45341 | I11: =COUNTIF('Purchase-Orders'!$D$3:$D$1000,B11) -> 5 | J11: =SUMIF('Purchase-Orders'!$D$3:$D$1000,B11,'Purchase-Orders'!$I$3:$I$1000) -> 187000 | K11: 4
A12: SUP-010 | B12: ClearView Office Systems | C12: Patricia Dizon | D12: p.dizon@clearviewoffice.com | E12: 0926 334 1098 | F12: Stationery | G12: Active | H12: 45082 | I12: =COUNTIF('Purchase-Orders'!$D$3:$D$1000,B12) -> 1 | J12: =SUMIF('Purchase-Orders'!$D$3:$D$1000,B12,'Purchase-Orders'!$I$3:$I$1000) -> 175 | K12: 4.3

Sheet Procurement-Requests
A1: Procurement Requests
A2: Request ID | B2: Date Requested | C2: Department | D2: Requested Item | E2: Category | F2: Quantity | G2: Priority | H2: Requested By | I2: Status | J2: Date Needed | K2: Approved By | L2: Remarks
A3: REQ-0001 | B3: 46043 | C3: Finance | D3: Bond Paper A4 | E3: =IFERROR(INDEX('Inventory-Master'!$C$3:$C$32,MATCH(D3,'Inventory-Master'!$B$3:$B$32,0)),"") -> Paper Products | F3: 30 | G3: Low | H3: Angela Bautista | I3: Pending | J3: 46051 | L3: Awaiting department head approval
A4: REQ-0002 | B4: 46075 | C4: Finance | D4: Notebook A5 | E4: =IFERROR(INDEX('Inventory-Master'!$C$3:$C$32,MATCH(D4,'Inventory-Master'!$B$3:$B$32,0)),"") -> Paper Products | F4: 20 | G4: Low | H4: Bea Santiago | I4: Pending | J4: 46090 | L4: Awaiting department head approval
A5: REQ-0003 | B5: 46101 | C5: Admin | D5: Document Envelope | E5: =IFERROR(INDEX('Inventory-Master'!$C$3:$C$32,MATCH(D5,'Inventory-Master'!$B$3:$B$32,0)),"") -> Filing & Storage | F5: 10 | G5: High | H5: Kristine Uy | I5: Rejected | J5: 46111 | L5: Insufficient budget for this cycle
A6: REQ-0004 | B6: 46127 | C6: Marketing | D6: Toner Cartridge | E6: =IFERROR(INDEX('Inventory-Master'!$C$3:$C$32,MATCH(D6,'Inventory-Master'!$B$3:$B$32,0)),"") -> Printing Supplies | F6: 50 | G6: Low | H6: Miguel Torres | I6: Fulfilled | J6: 46139 | K6: Edwin Castillo (Finance Mgr) | L6: Delivered and issued to requesting department
A7: REQ-0005 | B7: 46147 | C7: IT | D7: Printer Ink Yellow | E7: =IFERROR(INDEX('Inventory-Master'!$C$3:$C$32,MATCH(D7,'Inventory-Master'!$B$3:$B$32,0)),"") -> Printing Supplies | F7: 15 | G7: Low | H7: Kevin Ocampo | I7: Pending | J7: 46167 | L7: Awaiting department head approval
A8: REQ-0006 | B8: 46185 | C8: Marketing | D8: Toner Cartridge | E8: =IFERROR(INDEX('Inventory-Master'!$C$3:$C$32,MATCH(D8,'Inventory-Master'!$B$3:$B$32,0)),"") -> Printing Supplies | F8: 5 | G8: High | H8: Noel Villareal | I8: Pending | J8: 46206 | L8: Awaiting department head approval
A9: REQ-0007 | B9: 46035 | C9: Finance | D9: Document Envelope | E9: =IFERROR(INDEX('Inventory-Master'!$C$3:$C$32,MATCH(D9,'Inventory-Master'!$B$3:$B$32,0)),"") -> Filing & Storage | F9: 15 | G9: High | H9: Grace Manalo | I9: Fulfilled | J9: 46047 | K9: Cynthia Roque (Admin Mgr) | L9: Delivered and issued to requesting department
A10: REQ-0008 | B10: 46060 | C10: Finance | D10: Ballpen Black | E10: =IFERROR(INDEX('Inventory-Master'!$C$3:$C$32,MATCH(D10,'Inventory-Master'!$B$3:$B$32,0)),"") -> Writing Instruments | F10: 30 | G10: Low | H10: Ramon Aquino | I10: Fulfilled | J10: 46080 | K10: Rachel Gonzales (Ops Mgr) | L10: Delivered and issued to requesting department
A11: REQ-0009 | B11: 46109 | C11: Finance | D11: Paper Clips | E11: =IFERROR(INDEX('Inventory-Master'!$C$3:$C$32,MATCH(D11,'Inventory-Master'!$B$3:$B$32,0)),"") -> Office Equipment | F11: 15 | G11: Medium | H11: Julia Navarro | I11: Pending | J11: 46121 | L11: Awaiting department head approval
A12: REQ-0010 | B12: 46119 | C12: Marketing | D12: Printer Ink Cyan | E12: =IFERROR(INDEX('Inventory-Master'!$C$3:$C$32,MATCH(D12,'Inventory-Master'!$B$3:$B$32,0)),"") -> Printing Supplies | F12: 30 | G12: Medium | H12: Grace Manalo | I12: Fulfilled | J12: 46134 | K12: Cynthia Roque (Admin Mgr) | L12: Delivered and issued to requesting department
A13: REQ-0011 | B13: 46150 | C13: HR | D13: Rubber Bands | E13: =IFERROR(INDEX('Inventory-Master'!$C$3:$C$32,MATCH(D13,'Inventory-Master'!$B$3:$B$32,0)),"") -> Office Equipment | F13: 20 | G13: Low | H13: Paolo Salazar | I13: Fulfilled | J13: 46160 | K13: Cynthia Roque (Admin Mgr) | L13: Delivered and issued to requesting department
A14: REQ-0012 | B14: 46184 | C14: Admin | D14: Permanent Marker Black | E14: =IFERROR(INDEX('Inventory-Master'!$C$3:$C$32,MATCH(D14,'Inventory-Master'!$B$3:$B$32,0)),"") -> Writing Instruments | F14: 50 | G14: Low | H14: Julia Navarro | I14: Approved | J14: 46192 | K14: Rachel Gonzales (Ops Mgr) | L14: Approved, pending PO issuance
A15: REQ-0013 | B15: 46052 | C15: Operations | D15: Highlighter Yellow | E15: =IFERROR(INDEX('Inventory-Master'!$C$3:$C$32,MATCH(D15,'Inventory-Master'!$B$3:$B$32,0)),"") -> Writing Instruments | F15: 30 | G15: Medium | H15: Paolo Salazar | I15: Approved | J15: 46063 | K15: Rachel Gonzales (Ops Mgr) | L15: Approved, pending PO issuance
A16: REQ-0014 | B16: 46061 | C16: Marketing | D16: Printer Ink Magenta | E16: =IFERROR(INDEX('Inventory-Master'!$C$3:$C$32,MATCH(D16,'Inventory-Master'!$B$3:$B$32,0)),"") -> Printing Supplies | F16: 25 | G16: Medium | H16: Grace Manalo | I16: Approved | J16: 46071 | K16: Rachel Gonzales (Ops Mgr) | L16: Approved, pending PO issuance
A17: REQ-0015 | B17: 46098 | C17: Sales | D17: Stapler | E17: =IFERROR(INDEX('Inventory-Master'!$C$3:$C$32,MATCH(D17,'Inventory-Master'!$B$3:$B$32,0)),"") -> Office Equipment | F17: 50 | G17: Low | H17: Bea Santiago | I17: Pending | J17: 46107 | L17: Awaiting department head approval
A18: REQ-0016 | B18: 46138 | C18: Procurement | D18: Memo Pad | E18: =IFERROR(INDEX('Inventory-Master'!$C$3:$C$32,MATCH(D18,'Inventory-Master'!$B$3:$B$32,0)),"") -> Stationery | F18: 5 | G18: Medium | H18: Grace Manalo | I18: Fulfilled | J18: 46153 | K18: Edwin Castillo (Finance Mgr) | L18: Delivered and issued to requesting department
A19: REQ-0017 | B19: 46160 | C19: Admin | D19: Printer Ink Black | E19: =IFERROR(INDEX('Inventory-Master'!$C$3:$C$32,MATCH(D19,'Inventory-Master'!$B$3:$B$32,0)),"") -> Printing Supplies | F19: 30 | G19: Low | H19: Noel Villareal | I19: Fulfilled | J19: 46179 | K19: Cynthia Roque (Admin Mgr) | L19: Delivered and issued to requesting department
A20: REQ-0018 | B20: 46184 | C20: Finance | D20: Correction Tape | E20: =IFERROR(INDEX('Inventory-Master'!$C$3:$C$32,MATCH(D20,'Inventory-Master'!$B$3:$B$32,0)),"") -> Office Equipment | F20: 20 | G20: Low | H20: Carlos Dela Cruz | I20: Fulfilled | J20: 46205 | K20: Cynthia Roque (Admin Mgr) | L20: Delivered and issued to requesting department
A21: REQ-0019 | B21: 46031 | C21: HR | D21: Expanding File Folder | E21: =IFERROR(INDEX('Inventory-Master'!$C$3:$C$32,MATCH(D21,'Inventory-Master'!$B$3:$B$32,0)),"") -> Filing & Storage | F21: 5 | G21: High | H21: Ramon Aquino | I21: Fulfilled | J21: 46046 | K21: Cynthia Roque (Admin Mgr) | L21: Delivered and issued to requesting department
A22: REQ-0020 | B22: 46060 | C22: HR | D22: Scissors | E22: =IFERROR(INDEX('Inventory-Master'!$C$3:$C$32,MATCH(D22,'Inventory-Master'!$B$3:$B$32,0)),"") -> Office Equipment | F22: 50 | G22: Low | H22: Noel Villareal | I22: Fulfilled | J22: 46076 | K22: Edwin Castillo (Finance Mgr) | L22: Delivered and issued to requesting department
A23: REQ-0021 | B23: 46097 | C23: Admin | D23: Staple Wire | E23: =IFERROR(INDEX('Inventory-Master'!$C$3:$C$32,MATCH(D23,'Inventory-Master'!$B$3:$B$32,0)),"") -> Office Equipment | F23: 15 | G23: High | H23: Ramon Aquino | I23: Approved | J23: 46107 | K23: Cynthia Roque (Admin Mgr) | L23: Approved, pending PO issuance
A24: REQ-0022 | B24: 46115 | C24: Finance | D24: Printer Ink Magenta | E24: =IFERROR(INDEX('Inventory-Master'!$C$3:$C$32,MATCH(D24,'Inventory-Master'!$B$3:$B$32,0)),"") -> Printing Supplies | F24: 20 | G24: High | H24: Noel Villareal | I24: Fulfilled | J24: 46124 | K24: Cynthia Roque (Admin Mgr) | L24: Delivered and issued to requesting department
A25: REQ-0023 | B25: 46158 | C25: HR | D25: Whiteboard Marker Blue | E25: =IFERROR(INDEX('Inventory-Master'!$C$3:$C$32,MATCH(D25,'Inventory-Master'!$B$3:$B$32,0)),"") -> Writing Instruments | F25: 25 | G25: High | H25: Kevin Ocampo | I25: Fulfilled | J25: 46179 | K25: Cynthia Roque (Admin Mgr) | L25: Delivered and issued to requesting department
A26: REQ-0024 | B26: 46198 | C26: IT | D26: Printer Ink Cyan | E26: =IFERROR(INDEX('Inventory-Master'!$C$3:$C$32,MATCH(D26,'Inventory-Master'!$B$3:$B$32,0)),"") -> Printing Supplies | F26: 15 | G26: Medium | H26: Paolo Salazar | I26: Fulfilled | J26: 46212 | K26: Cynthia Roque (Admin Mgr) | L26: Delivered and issued to requesting department
A27: REQ-0025 | B27: 46037 | C27: Finance | D27: Permanent Marker Black | E27: =IFERROR(INDEX('Inventory-Master'!$C$3:$C$32,MATCH(D27,'Inventory-Master'!$B$3:$B$32,0)),"") -> Writing Instruments | F27: 10 | G27: Low | H27: Carlos Dela Cruz | I27: Rejected | J27: 46047 | L27: Insufficient budget for this cycle
A28: REQ-0026 | B28: 46072 | C28: IT | D28: Bond Paper A4 | E28: =IFERROR(INDEX('Inventory-Master'!$C$3:$C$32,MATCH(D28,'Inventory-Master'!$B$3:$B$32,0)),"") -> Paper Products | F28: 5 | G28: High | H28: Carlos Dela Cruz | I28: Approved | J28: 46093 | K28: Rachel Gonzales (Ops Mgr) | L28: Approved, pending PO issuance
A29: REQ-0027 | B29: 46109 | C29: Operations | D29: Stapler | E29: =IFERROR(INDEX('Inventory-Master'!$C$3:$C$32,MATCH(D29,'Inventory-Master'!$B$3:$B$32,0)),"") -> Office Equipment | F29: 25 | G29: Low | H29: Paolo Salazar | I29: Approved | J29: 46124 | K29: Rachel Gonzales (Ops Mgr) | L29: Approved, pending PO issuance
A30: REQ-0028 | B30: 46136 | C30: Sales | D30: Permanent Marker Black | E30: =IFERROR(INDEX('Inventory-Master'!$C$3:$C$32,MATCH(D30,'Inventory-Master'!$B$3:$B$32,0)),"") -> Writing Instruments | F30: 50 | G30: Medium | H30: Kevin Ocampo | I30: Pending | J30: 46144 | L30: Awaiting department head approval
A31: REQ-0029 | B31: 46164 | C31: Procurement | D31: Scissors | E31: =IFERROR(INDEX('Inventory-Master'!$C$3:$C$32,MATCH(D31,'Inventory-Master'!$B$3:$B$32,0)),"") -> Office Equipment | F31: 20 | G31: Medium | H31: Kristine Uy | I31: Pending | J31: 46181 | L31: Awaiting department head approval
A32: REQ-0030 | B32: 46194 | C32: Finance | D32: Ballpen Black | E32: =IFERROR(INDEX('Inventory-Master'!$C$3:$C$32,MATCH(D32,'Inventory-Master'!$B$3:$B$32,0)),"") -> Writing Instruments | F32: 20 | G32: High | H32: Bea Santiago | I32: Approved | J32: 46204 | K32: Cynthia Roque (Admin Mgr) | L32: Approved, pending PO issuance

Sheet Purchase-Orders
A1: Purchase Orders
A2: PO Number | B2: PO Date | C2: Request ID | D2: Supplier | E2: Item | F2: Category | G2: Unit Cost | H2: Qty Ordered | I2: Total Cost | J2: Status | K2: Expected Delivery | L2: Actual Delivery | M2: Days to Deliver | N2: Remarks
A3: PO-0001 | B3: 46054 | C3: REQ-0013 | D3: Signature Pens & More | E3: Highlighter Yellow | F3: =IFERROR(INDEX('Inventory-Master'!$C$3:$C$32,MATCH(E3,'Inventory-Master'!$B$3:$B$32,0)),"") -> Writing Instruments | G3: =IFERROR(INDEX('Inventory-Master'!$G$3:$G$32,MATCH(E3,'Inventory-Master'!$B$3:$B$32,0)),0) -> 48 | H3: 30 | I3: =G3*H3 -> 1440 | J3: Delivered | K3: 46063 | L3: 46064 | M3: =IFERROR(IF(L3="","",L3-B3),"") -> 10 | N3: Received in full and verified
A4: PO-0002 | B4: 46061 | C4: REQ-0008 | D4: Signature Pens & More | E4: Ballpen Black | F4: =IFERROR(INDEX('Inventory-Master'!$C$3:$C$32,MATCH(E4,'Inventory-Master'!$B$3:$B$32,0)),"") -> Writing Instruments | G4: =IFERROR(INDEX('Inventory-Master'!$G$3:$G$32,MATCH(E4,'Inventory-Master'!$B$3:$B$32,0)),0) -> 70 | H4: 30 | I4: =G4*H4 -> 2100 | J4: Ordered | K4: 46075 | M4: =IFERROR(IF(L4="","",L4-B4),"") | N4: Order confirmed, in transit
A5: PO-0003 | B5: 46112 | C5: REQ-0027 | D5: Workspace Equipment Corp. | E5: Stapler | F5: =IFERROR(INDEX('Inventory-Master'!$C$3:$C$32,MATCH(E5,'Inventory-Master'!$B$3:$B$32,0)),"") -> Office Equipment | G5: =IFERROR(INDEX('Inventory-Master'!$G$3:$G$32,MATCH(E5,'Inventory-Master'!$B$3:$B$32,0)),0) -> 35 | H5: 25 | I5: =G5*H5 -> 875 | J5: Delivered | K5: 46126 | L5: 46125 | M5: =IFERROR(IF(L5="","",L5-B5),"") -> 13 | N5: Received in full and verified
A6: PO-0004 | B6: 46074 | C6: REQ-0026 | D6: Prime Paper Solutions | E6: Bond Paper A4 | F6: =IFERROR(INDEX('Inventory-Master'!$C$3:$C$32,MATCH(E6,'Inventory-Master'!$B$3:$B$32,0)),"") -> Paper Products | G6: =IFERROR(INDEX('Inventory-Master'!$G$3:$G$32,MATCH(E6,'Inventory-Master'!$B$3:$B$32,0)),0) -> 130 | H6: 5 | I6: =G6*H6 -> 650 | J6: Ordered | K6: 46081 | M6: =IFERROR(IF(L6="","",L6-B6),"") | N6: Order confirmed, in transit
A7: PO-0005 | B7: 46199 | C7: REQ-0024 | D7: BizForm Print Co. | E7: Printer Ink Cyan | F7: =IFERROR(INDEX('Inventory-Master'!$C$3:$C$32,MATCH(E7,'Inventory-Master'!$B$3:$B$32,0)),"") -> Printing Supplies | G7: =IFERROR(INDEX('Inventory-Master'!$G$3:$G$32,MATCH(E7,'Inventory-Master'!$B$3:$B$32,0)),0) -> 100 | H7: 15 | I7: =G7*H7 -> 1500 | J7: Pending | K7: 46213 | M7: =IFERROR(IF(L7="","",L7-B7),"") | N7: Awaiting supplier confirmation
A8: PO-0006 | B8: 46162 | C8: REQ-0017 | D8: PrintTech Supplies Inc. | E8: Printer Ink Black | F8: =IFERROR(INDEX('Inventory-Master'!$C$3:$C$32,MATCH(E8,'Inventory-Master'!$B$3:$B$32,0)),"") -> Printing Supplies | G8: =IFERROR(INDEX('Inventory-Master'!$G$3:$G$32,MATCH(E8,'Inventory-Master'!$B$3:$B$32,0)),0) -> 100 | H8: 30 | I8: =G8*H8 -> 3000 | J8: Cancelled | K8: 46170 | M8: =IFERROR(IF(L8="","",L8-B8),"") | N8: Cancelled due to supplier stock-out
A9: PO-0007 | B9: 46033 | C9: REQ-0019 | D9: SecureFile Solutions | E9: Expanding File Folder | F9: =IFERROR(INDEX('Inventory-Master'!$C$3:$C$32,MATCH(E9,'Inventory-Master'!$B$3:$B$32,0)),"") -> Filing & Storage | G9: =IFERROR(INDEX('Inventory-Master'!$G$3:$G$32,MATCH(E9,'Inventory-Master'!$B$3:$B$32,0)),0) -> 150 | H9: 5 | I9: =G9*H9 -> 750 | J9: Delivered | K9: 46043 | L9: 46044 | M9: =IFERROR(IF(L9="","",L9-B9),"") -> 11 | N9: Received in full and verified
A10: PO-0008 | B10: 46185 | C10: REQ-0018 | D10: Office Essentials Trading | E10: Correction Tape | F10: =IFERROR(INDEX('Inventory-Master'!$C$3:$C$32,MATCH(E10,'Inventory-Master'!$B$3:$B$32,0)),"") -> Office Equipment | G10: =IFERROR(INDEX('Inventory-Master'!$G$3:$G$32,MATCH(E10,'Inventory-Master'!$B$3:$B$32,0)),0) -> 15 | H10: 20 | I10: =G10*H10 -> 300 | J10: Delivered | K10: 46192 | L10: 46194 | M10: =IFERROR(IF(L10="","",L10-B10),"") -> 9 | N10: Received in full and verified
A11: PO-0009 | B11: 46128 | C11: REQ-0004 | D11: BizForm Print Co. | E11: Toner Cartridge | F11: =IFERROR(INDEX('Inventory-Master'!$C$3:$C$32,MATCH(E11,'Inventory-Master'!$B$3:$B$32,0)),"") -> Printing Supplies | G11: =IFERROR(INDEX('Inventory-Master'!$G$3:$G$32,MATCH(E11,'Inventory-Master'!$B$3:$B$32,0)),0) -> 3000 | H11: 50 | I11: =G11*H11 -> 150000 | J11: Delivered | K11: 46140 | L11: 46140 | M11: =IFERROR(IF(L11="","",L11-B11),"") -> 12 | N11: Received in full and verified
A12: PO-0010 | B12: 46062 | C12: REQ-0020 | D12: Workspace Equipment Corp. | E12: Scissors | F12: =IFERROR(INDEX('Inventory-Master'!$C$3:$C$32,MATCH(E12,'Inventory-Master'!$B$3:$B$32,0)),"") -> Office Equipment | G12: =IFERROR(INDEX('Inventory-Master'!$G$3:$G$32,MATCH(E12,'Inventory-Master'!$B$3:$B$32,0)),0) -> 10 | H12: 50 | I12: =G12*H12 -> 500 | J12: Ordered | K12: 46075 | M12: =IFERROR(IF(L12="","",L12-B12),"") | N12: Order confirmed, in transit
A13: PO-0011 | B13: 46160 | C13: REQ-0023 | D13: Signature Pens & More | E13: Whiteboard Marker Blue | F13: =IFERROR(INDEX('Inventory-Master'!$C$3:$C$32,MATCH(E13,'Inventory-Master'!$B$3:$B$32,0)),"") -> Writing Instruments | G13: =IFERROR(INDEX('Inventory-Master'!$G$3:$G$32,MATCH(E13,'Inventory-Master'!$B$3:$B$32,0)),0) -> 15 | H13: 25 | I13: =G13*H13 -> 375 | J13: Partially Delivered | K13: 46168 | L13: 46168 | M13: =IFERROR(IF(L13="","",L13-B13),"") -> 8 | N13: Partial shipment received; balance pending
A14: PO-0012 | B14: 46198 | C14: REQ-0030 | D14: Signature Pens & More | E14: Ballpen Black | F14: =IFERROR(INDEX('Inventory-Master'!$C$3:$C$32,MATCH(E14,'Inventory-Master'!$B$3:$B$32,0)),"") -> Writing Instruments | G14: =IFERROR(INDEX('Inventory-Master'!$G$3:$G$32,MATCH(E14,'Inventory-Master'!$B$3:$B$32,0)),0) -> 70 | H14: 20 | I14: =G14*H14 -> 1400 | J14: Pending | K14: 46208 | M14: =IFERROR(IF(L14="","",L14-B14),"") | N14: Awaiting supplier confirmation
A15: PO-0013 | B15: 46038 | C15: REQ-0007 | D15: SecureFile Solutions | E15: Document Envelope | F15: =IFERROR(INDEX('Inventory-Master'!$C$3:$C$32,MATCH(E15,'Inventory-Master'!$B$3:$B$32,0)),"") -> Filing & Storage | G15: =IFERROR(INDEX('Inventory-Master'!$G$3:$G$32,MATCH(E15,'Inventory-Master'!$B$3:$B$32,0)),0) -> 750 | H15: 15 | I15: =G15*H15 -> 11250 | J15: Delivered | K15: 46046 | L15: 46045 | M15: =IFERROR(IF(L15="","",L15-B15),"") -> 7 | N15: Received in full and verified
A16: PO-0014 | B16: 46122 | C16: REQ-0010 | D16: BizForm Print Co. | E16: Printer Ink Cyan | F16: =IFERROR(INDEX('Inventory-Master'!$C$3:$C$32,MATCH(E16,'Inventory-Master'!$B$3:$B$32,0)),"") -> Printing Supplies | G16: =IFERROR(INDEX('Inventory-Master'!$G$3:$G$32,MATCH(E16,'Inventory-Master'!$B$3:$B$32,0)),0) -> 100 | H16: 30 | I16: =G16*H16 -> 3000 | J16: Pending | K16: 46133 | M16: =IFERROR(IF(L16="","",L16-B16),"") | N16: Awaiting supplier confirmation
A17: PO-0015 | B17: 46062 | C17: REQ-0014 | D17: BizForm Print Co. | E17: Printer Ink Magenta | F17: =IFERROR(INDEX('Inventory-Master'!$C$3:$C$32,MATCH(E17,'Inventory-Master'!$B$3:$B$32,0)),"") -> Printing Supplies | G17: =IFERROR(INDEX('Inventory-Master'!$G$3:$G$32,MATCH(E17,'Inventory-Master'!$B$3:$B$32,0)),0) -> 100 | H17: 25 | I17: =G17*H17 -> 2500 | J17: Delivered | K17: 46070 | L17: 46069 | M17: =IFERROR(IF(L17="","",L17-B17),"") -> 7 | N17: Received in full and verified
A18: PO-0016 | B18: 46141 | C18: REQ-0016 | D18: ClearView Office Systems | E18: Memo Pad | F18: =IFERROR(INDEX('Inventory-Master'!$C$3:$C$32,MATCH(E18,'Inventory-Master'!$B$3:$B$32,0)),"") -> Stationery | G18: =IFERROR(INDEX('Inventory-Master'!$G$3:$G$32,MATCH(E18,'Inventory-Master'!$B$3:$B$32,0)),0) -> 35 | H18: 5 | I18: =G18*H18 -> 175 | J18: Delivered | K18: 46150 | L18: 46150 | M18: =IFERROR(IF(L18="","",L18-B18),"") -> 9 | N18: Received in full and verified
A19: PO-0017 | B19: 46187 | C19: REQ-0012 | D19: Signature Pens & More | E19: Permanent Marker Black | F19: =IFERROR(INDEX('Inventory-Master'!$C$3:$C$32,MATCH(E19,'Inventory-Master'!$B$3:$B$32,0)),"") -> Writing Instruments | G19: =IFERROR(INDEX('Inventory-Master'!$G$3:$G$32,MATCH(E19,'Inventory-Master'!$B$3:$B$32,0)),0) -> 15 | H19: 50 | I19: =G19*H19 -> 750 | J19: Delivered | K19: 46197 | L19: 46200 | M19: =IFERROR(IF(L19="","",L19-B19),"") -> 13 | N19: Received in full and verified
A20: PO-0018 | B20: 46100 | C20: REQ-0021 | D20: Workspace Equipment Corp. | E20: Staple Wire | F20: =IFERROR(INDEX('Inventory-Master'!$C$3:$C$32,MATCH(E20,'Inventory-Master'!$B$3:$B$32,0)),"") -> Office Equipment | G20: =IFERROR(INDEX('Inventory-Master'!$G$3:$G$32,MATCH(E20,'Inventory-Master'!$B$3:$B$32,0)),0) -> 40 | H20: 15 | I20: =G20*H20 -> 600 | J20: Ordered | K20: 46107 | M20: =IFERROR(IF(L20="","",L20-B20),"") | N20: Order confirmed, in transit
A21: PO-0019 | B21: 46151 | C21: REQ-0011 | D21: Workspace Equipment Corp. | E21: Rubber Bands | F21: =IFERROR(INDEX('Inventory-Master'!$C$3:$C$32,MATCH(E21,'Inventory-Master'!$B$3:$B$32,0)),"") -> Office Equipment | G21: =IFERROR(INDEX('Inventory-Master'!$G$3:$G$32,MATCH(E21,'Inventory-Master'!$B$3:$B$32,0)),0) -> 45 | H21: 20 | I21: =G21*H21 -> 900 | J21: Delivered | K21: 46158 | L21: 46156 | M21: =IFERROR(IF(L21="","",L21-B21),"") -> 5 | N21: Received in full and verified
A22: PO-0020 | B22: 46118 | C22: REQ-0022 | D22: PrintTech Supplies Inc. | E22: Printer Ink Magenta | F22: =IFERROR(INDEX('Inventory-Master'!$C$3:$C$32,MATCH(E22,'Inventory-Master'!$B$3:$B$32,0)),"") -> Printing Supplies | G22: =IFERROR(INDEX('Inventory-Master'!$G$3:$G$32,MATCH(E22,'Inventory-Master'!$B$3:$B$32,0)),0) -> 100 | H22: 20 | I22: =G22*H22 -> 2000 | J22: Delivered | K22: 46129 | L22: 46128 | M22: =IFERROR(IF(L22="","",L22-B22),"") -> 10 | N22: Received in full and verified
A23: PO-0021 | B23: 46105 | D23: Workspace Equipment Corp. | E23: Rubber Bands | F23: =IFERROR(INDEX('Inventory-Master'!$C$3:$C$32,MATCH(E23,'Inventory-Master'!$B$3:$B$32,0)),"") -> Office Equipment | G23: =IFERROR(INDEX('Inventory-Master'!$G$3:$G$32,MATCH(E23,'Inventory-Master'!$B$3:$B$32,0)),0) -> 45 | H23: 60 | I23: =G23*H23 -> 2700 | J23: Delivered | K23: 46113 | L23: 46111 | M23: =IFERROR(IF(L23="","",L23-B23),"") -> 6 | N23: Received in full and verified
A24: PO-0022 | B24: 46141 | D24: PrintTech Supplies Inc. | E24: Printer Ink Cyan | F24: =IFERROR(INDEX('Inventory-Master'!$C$3:$C$32,MATCH(E24,'Inventory-Master'!$B$3:$B$32,0)),"") -> Printing Supplies | G24: =IFERROR(INDEX('Inventory-Master'!$G$3:$G$32,MATCH(E24,'Inventory-Master'!$B$3:$B$32,0)),0) -> 100 | H24: 20 | I24: =G24*H24 -> 2000 | J24: Delivered | K24: 46150 | L24: 46151 | M24: =IFERROR(IF(L24="","",L24-B24),"") -> 10 | N24: Received in full and verified
A25: PO-0023 | B25: 46147 | D25: Signature Pens & More | E25: Ballpen Black | F25: =IFERROR(INDEX('Inventory-Master'!$C$3:$C$32,MATCH(E25,'Inventory-Master'!$B$3:$B$32,0)),"") -> Writing Instruments | G25: =IFERROR(INDEX('Inventory-Master'!$G$3:$G$32,MATCH(E25,'Inventory-Master'!$B$3:$B$32,0)),0) -> 70 | H25: 30 | I25: =G25*H25 -> 2100 | J25: Delivered | K25: 46154 | L25: 46154 | M25: =IFERROR(IF(L25="","",L25-B25),"") -> 7 | N25: Received in full and verified
A26: PO-0024 | B26: 46180 | D26: PrintTech Supplies Inc. | E26: Printer Ink Black | F26: =IFERROR(INDEX('Inventory-Master'!$C$3:$C$32,MATCH(E26,'Inventory-Master'!$B$3:$B$32,0)),"") -> Printing Supplies | G26: =IFERROR(INDEX('Inventory-Master'!$G$3:$G$32,MATCH(E26,'Inventory-Master'!$B$3:$B$32,0)),0) -> 100 | H26: 20 | I26: =G26*H26 -> 2000 | J26: Ordered | K26: 46193 | M26: =IFERROR(IF(L26="","",L26-B26),"") | N26: Order confirmed, in transit
A27: PO-0025 | B27: 46042 | D27: PrintTech Supplies Inc. | E27: Printer Ink Magenta | F27: =IFERROR(INDEX('Inventory-Master'!$C$3:$C$32,MATCH(E27,'Inventory-Master'!$B$3:$B$32,0)),"") -> Printing Supplies | G27: =IFERROR(INDEX('Inventory-Master'!$G$3:$G$32,MATCH(E27,'Inventory-Master'!$B$3:$B$32,0)),0) -> 100 | H27: 20 | I27: =G27*H27 -> 2000 | J27: Delivered | K27: 46051 | L27: 46052 | M27: =IFERROR(IF(L27="","",L27-B27),"") -> 10 | N27: Received in full and verified
A28: PO-0026 | B28: 46054 | D28: Signature Pens & More | E28: Eraser | F28: =IFERROR(INDEX('Inventory-Master'!$C$3:$C$32,MATCH(E28,'Inventory-Master'!$B$3:$B$32,0)),"") -> Writing Instruments | G28: =IFERROR(INDEX('Inventory-Master'!$G$3:$G$32,MATCH(E28,'Inventory-Master'!$B$3:$B$32,0)),0) -> 50 | H28: 30 | I28: =G28*H28 -> 1500 | J28: Delivered | K28: 46064 | L28: 46064 | M28: =IFERROR(IF(L28="","",L28-B28),"") -> 10 | N28: Received in full and verified
A29: PO-0027 | B29: 46087 | D29: BizForm Print Co. | E29: Toner Cartridge | F29: =IFERROR(INDEX('Inventory-Master'!$C$3:$C$32,MATCH(E29,'Inventory-Master'!$B$3:$B$32,0)),"") -> Printing Supplies | G29: =IFERROR(INDEX('Inventory-Master'!$G$3:$G$32,MATCH(E29,'Inventory-Master'!$B$3:$B$32,0)),0) -> 3000 | H29: 10 | I29: =G29*H29 -> 30000 | J29: Delivered | K29: 46101 | L29: 46100 | M29: =IFERROR(IF(L29="","",L29-B29),"") -> 13 | N29: Received in full and verified
A30: PO-0028 | B30: 46119 | D30: TechLink Accessories | E30: USB Flash Drive 32GB | F30: =IFERROR(INDEX('Inventory-Master'!$C$3:$C$32,MATCH(E30,'Inventory-Master'!$B$3:$B$32,0)),"") -> IT Accessories | G30: =IFERROR(INDEX('Inventory-Master'!$G$3:$G$32,MATCH(E30,'Inventory-Master'!$B$3:$B$32,0)),0) -> 600 | H30: 40 | I30: =G30*H30 -> 24000 | J30: Ordered | K30: 46129 | M30: =IFERROR(IF(L30="","",L30-B30),"") | N30: Order confirmed, in transit

Sheet Budget-Tracker
A1: Budget & Spending Analysis
A2: Month | B2: Category | C2: Budget Allocated | D2: Actual Spend | E2: Variance | F2: Variance % | G2: Status
A3: 46023 | B3: Paper Products | C3: 16220 | D3: =SUMIFS('Purchase-Orders'!$I$3:$I$30,'Purchase-Orders'!$B$3:$B$30,">="&A3,'Purchase-Orders'!$B$3:$B$30,"<"&EDATE(A3,1),'Purchase-Orders'!$F$3:$F$30,B3) -> 0 | E3: =C3-D3 -> 16220 | F3: =IFERROR(E3/C3,0) -> 1 | G3: =IF(D3>C3,"Over Budget","Within Budget") -> Within Budget
A4: 46023 | B4: Writing Instruments | C4: 7800 | D4: =SUMIFS('Purchase-Orders'!$I$3:$I$30,'Purchase-Orders'!$B$3:$B$30,">="&A4,'Purchase-Orders'!$B$3:$B$30,"<"&EDATE(A4,1),'Purchase-Orders'!$F$3:$F$30,B4) -> 0 | E4: =C4-D4 -> 7800 | F4: =IFERROR(E4/C4,0) -> 1 | G4: =IF(D4>C4,"Over Budget","Within Budget") -> Within Budget
A5: 46023 | B5: Office Equipment | C5: 13060 | D5: =SUMIFS('Purchase-Orders'!$I$3:$I$30,'Purchase-Orders'!$B$3:$B$30,">="&A5,'Purchase-Orders'!$B$3:$B$30,"<"&EDATE(A5,1),'Purchase-Orders'!$F$3:$F$30,B5) -> 0 | E5: =C5-D5 -> 13060 | F5: =IFERROR(E5/C5,0) -> 1 | G5: =IF(D5>C5,"Over Budget","Within Budget") -> Within Budget
A6: 46023 | B6: Filing & Storage | C6: 16910 | D6: =SUMIFS('Purchase-Orders'!$I$3:$I$30,'Purchase-Orders'!$B$3:$B$30,">="&A6,'Purchase-Orders'!$B$3:$B$30,"<"&EDATE(A6,1),'Purchase-Orders'!$F$3:$F$30,B6) -> 12000 | E6: =C6-D6 -> 4910 | F6: =IFERROR(E6/C6,0) -> 0.29036073 | G6: =IF(D6>C6,"Over Budget","Within Budget") -> Within Budget
A7: 46023 | B7: Stationery | C7: 6110 | D7: =SUMIFS('Purchase-Orders'!$I$3:$I$30,'Purchase-Orders'!$B$3:$B$30,">="&A7,'Purchase-Orders'!$B$3:$B$30,"<"&EDATE(A7,1),'Purchase-Orders'!$F$3:$F$30,B7) -> 0 | E7: =C7-D7 -> 6110 | F7: =IFERROR(E7/C7,0) -> 1 | G7: =IF(D7>C7,"Over Budget","Within Budget") -> Within Budget
A8: 46023 | B8: Printing Supplies | C8: 26650 | D8: =SUMIFS('Purchase-Orders'!$I$3:$I$30,'Purchase-Orders'!$B$3:$B$30,">="&A8,'Purchase-Orders'!$B$3:$B$30,"<"&EDATE(A8,1),'Purchase-Orders'!$F$3:$F$30,B8) -> 2000 | E8: =C8-D8 -> 24650 | F8: =IFERROR(E8/C8,0) -> 0.9249531 | G8: =IF(D8>C8,"Over Budget","Within Budget") -> Within Budget
A9: 46023 | B9: IT Accessories | C9: 9490 | D9: =SUMIFS('Purchase-Orders'!$I$3:$I$30,'Purchase-Orders'!$B$3:$B$30,">="&A9,'Purchase-Orders'!$B$3:$B$30,"<"&EDATE(A9,1),'Purchase-Orders'!$F$3:$F$30,B9) -> 0 | E9: =C9-D9 -> 9490 | F9: =IFERROR(E9/C9,0) -> 1 | G9: =IF(D9>C9,"Over Budget","Within Budget") -> Within Budget
A10: 46023 | B10: Packaging Materials | C10: 9350 | D10: =SUMIFS('Purchase-Orders'!$I$3:$I$30,'Purchase-Orders'!$B$3:$B$30,">="&A10,'Purchase-Orders'!$B$3:$B$30,"<"&EDATE(A10,1),'Purchase-Orders'!$F$3:$F$30,B10) -> 0 | E10: =C10-D10 -> 9350 | F10: =IFERROR(E10/C10,0) -> 1 | G10: =IF(D10>C10,"Over Budget","Within Budget") -> Within Budget
A11: 46054 | B11: Paper Products | C11: 14400 | D11: =SUMIFS('Purchase-Orders'!$I$3:$I$30,'Purchase-Orders'!$B$3:$B$30,">="&A11,'Purchase-Orders'!$B$3:$B$30,"<"&EDATE(A11,1),'Purchase-Orders'!$F$3:$F$30,B11) -> 650 | E11: =C11-D11 -> 13750 | F11: =IFERROR(E11/C11,0) -> 0.95486111 | G11: =IF(D11>C11,"Over Budget","Within Budget") -> Within Budget
A12: 46054 | B12: Writing Instruments | C12: 8290 | D12: =SUMIFS('Purchase-Orders'!$I$3:$I$30,'Purchase-Orders'!$B$3:$B$30,">="&A12,'Purchase-Orders'!$B$3:$B$30,"<"&EDATE(A12,1),'Purchase-Orders'!$F$3:$F$30,B12) -> 5040 | E12: =C12-D12 -> 3250 | F12: =IFERROR(E12/C12,0) -> 0.3920386 | G12: =IF(D12>C12,"Over Budget","Within Budget") -> Within Budget
A13: 46054 | B13: Office Equipment | C13: 12730 | D13: =SUMIFS('Purchase-Orders'!$I$3:$I$30,'Purchase-Orders'!$B$3:$B$30,">="&A13,'Purchase-Orders'!$B$3:$B$30,"<"&EDATE(A13,1),'Purchase-Orders'!$F$3:$F$30,B13) -> 500 | E13: =C13-D13 -> 12230 | F13: =IFERROR(E13/C13,0) -> 0.9607227 | G13: =IF(D13>C13,"Over Budget","Within Budget") -> Within Budget
A14: 46054 | B14: Filing & Storage | C14: 19070 | D14: =SUMIFS('Purchase-Orders'!$I$3:$I$30,'Purchase-Orders'!$B$3:$B$30,">="&A14,'Purchase-Orders'!$B$3:$B$30,"<"&EDATE(A14,1),'Purchase-Orders'!$F$3:$F$30,B14) -> 0 | E14: =C14-D14 -> 19070 | F14: =IFERROR(E14/C14,0) -> 1 | G14: =IF(D14>C14,"Over Budget","Within Budget") -> Within Budget
... A50: 46174 | B50: Packaging Materials | C50: 8740 | D50: =SUMIFS('Purchase-Orders'!$I$3:$I$30,'Purchase-Orders'!$B$3:$B$30,">="&A50,'Purchase-Orders'!$B$3:$B$30,"<"&EDATE(A50,1),'Purchase-Orders'!$F$3:$F$30,B50) -> 0 | E50: =C50-D50 -> 8740 | F50: =IFERROR(E50/C50,0) -> 1 | G50: =IF(D50>C50,"Over Budget","Within Budget") -> Within Budget

Sheet Monthly-Report
A1: Monthly Procurement Report
A2: Month | B2: Total Requests | C2: Approved / Fulfilled | D2: Pending Requests | E2: Total POs Issued | F2: Total Procurement Spend | G2: Total Stock Issued Value | H2: Avg PO Value
A3: 46023 | B3: =COUNTIFS('Procurement-Requests'!$B$3:$B$32,">="&A3,'Procurement-Requests'!$B$3:$B$32,"<"&EDATE(A3,1)) -> 5 | C3: =COUNTIFS('Procurement-Requests'!$B$3:$B$32,">="&A3,'Procurement-Requests'!$B$3:$B$32,"<"&EDATE(A3,1),'Procurement-Requests'!$I$3:$I$32,"Approved")+COUNTIFS('Procurement-Requests'!$B$3:$B$32,">="&A3,'Procurement-Requests'!$B$3:$B$32,"<"&EDATE(A3,1),'Procurement-Requests'!$I$3:$I$32,"Fulfilled") -> 3 | D3: =COUNTIFS('Procurement-Requests'!$B$3:$B$32,">="&A3,'Procurement-Requests'!$B$3:$B$32,"<"&EDATE(A3,1),'Procurement-Requests'!$I$3:$I$32,"Pending") -> 1 | E3: =COUNTIFS('Purchase-Orders'!$B$3:$B$30,">="&A3,'Purchase-Orders'!$B$3:$B$30,"<"&EDATE(A3,1)) -> 3 | F3: =SUMIFS('Purchase-Orders'!$I$3:$I$30,'Purchase-Orders'!$B$3:$B$30,">="&A3,'Purchase-Orders'!$B$3:$B$30,"<"&EDATE(A3,1)) -> 14000 | G3: =SUMIFS('Stock-Issuance'!$H$3:$H$47,'Stock-Issuance'!$B$3:$B$47,">="&A3,'Stock-Issuance'!$B$3:$B$47,"<"&EDATE(A3,1)) -> 9690 | H3: =IFERROR(F3/E3,0) -> 4666.6667
A4: 46054 | B4: =COUNTIFS('Procurement-Requests'!$B$3:$B$32,">="&A4,'Procurement-Requests'!$B$3:$B$32,"<"&EDATE(A4,1)) -> 5 | C4: =COUNTIFS('Procurement-Requests'!$B$3:$B$32,">="&A4,'Procurement-Requests'!$B$3:$B$32,"<"&EDATE(A4,1),'Procurement-Requests'!$I$3:$I$32,"Approved")+COUNTIFS('Procurement-Requests'!$B$3:$B$32,">="&A4,'Procurement-Requests'!$B$3:$B$32,"<"&EDATE(A4,1),'Procurement-Requests'!$I$3:$I$32,"Fulfilled") -> 4 | D4: =COUNTIFS('Procurement-Requests'!$B$3:$B$32,">="&A4,'Procurement-Requests'!$B$3:$B$32,"<"&EDATE(A4,1),'Procurement-Requests'!$I$3:$I$32,"Pending") -> 1 | E4: =COUNTIFS('Purchase-Orders'!$B$3:$B$30,">="&A4,'Purchase-Orders'!$B$3:$B$30,"<"&EDATE(A4,1)) -> 6 | F4: =SUMIFS('Purchase-Orders'!$I$3:$I$30,'Purchase-Orders'!$B$3:$B$30,">="&A4,'Purchase-Orders'!$B$3:$B$30,"<"&EDATE(A4,1)) -> 8690 | G4: =SUMIFS('Stock-Issuance'!$H$3:$H$47,'Stock-Issuance'!$B$3:$B$47,">="&A4,'Stock-Issuance'!$B$3:$B$47,"<"&EDATE(A4,1)) -> 10689 | H4: =IFERROR(F4/E4,0) -> 1448.3333
A5: 46082 | B5: =COUNTIFS('Procurement-Requests'!$B$3:$B$32,">="&A5,'Procurement-Requests'!$B$3:$B$32,"<"&EDATE(A5,1)) -> 5 | C5: =COUNTIFS('Procurement-Requests'!$B$3:$B$32,">="&A5,'Procurement-Requests'!$B$3:$B$32,"<"&EDATE(A5,1),'Procurement-Requests'!$I$3:$I$32,"Approved")+COUNTIFS('Procurement-Requests'!$B$3:$B$32,">="&A5,'Procurement-Requests'!$B$3:$B$32,"<"&EDATE(A5,1),'Procurement-Requests'!$I$3:$I$32,"Fulfilled") -> 2 | D5: =COUNTIFS('Procurement-Requests'!$B$3:$B$32,">="&A5,'Procurement-Requests'!$B$3:$B$32,"<"&EDATE(A5,1),'Procurement-Requests'!$I$3:$I$32,"Pending") -> 2 | E5: =COUNTIFS('Purchase-Orders'!$B$3:$B$30,">="&A5,'Purchase-Orders'!$B$3:$B$30,"<"&EDATE(A5,1)) -> 4 | F5: =SUMIFS('Purchase-Orders'!$I$3:$I$30,'Purchase-Orders'!$B$3:$B$30,">="&A5,'Purchase-Orders'!$B$3:$B$30,"<"&EDATE(A5,1)) -> 34175 | G5: =SUMIFS('Stock-Issuance'!$H$3:$H$47,'Stock-Issuance'!$B$3:$B$47,">="&A5,'Stock-Issuance'!$B$3:$B$47,"<"&EDATE(A5,1)) -> 23740 | H5: =IFERROR(F5/E5,0) -> 8543.75
A6: 46113 | B6: =COUNTIFS('Procurement-Requests'!$B$3:$B$32,">="&A6,'Procurement-Requests'!$B$3:$B$32,"<"&EDATE(A6,1)) -> 5 | C6: =COUNTIFS('Procurement-Requests'!$B$3:$B$32,">="&A6,'Procurement-Requests'!$B$3:$B$32,"<"&EDATE(A6,1),'Procurement-Requests'!$I$3:$I$32,"Approved")+COUNTIFS('Procurement-Requests'!$B$3:$B$32,">="&A6,'Procurement-Requests'!$B$3:$B$32,"<"&EDATE(A6,1),'Procurement-Requests'!$I$3:$I$32,"Fulfilled") -> 4 | D6: =COUNTIFS('Procurement-Requests'!$B$3:$B$32,">="&A6,'Procurement-Requests'!$B$3:$B$32,"<"&EDATE(A6,1),'Procurement-Requests'!$I$3:$I$32,"Pending") -> 1 | E6: =COUNTIFS('Purchase-Orders'!$B$3:$B$30,">="&A6,'Purchase-Orders'!$B$3:$B$30,"<"&EDATE(A6,1)) -> 6 | F6: =SUMIFS('Purchase-Orders'!$I$3:$I$30,'Purchase-Orders'!$B$3:$B$30,">="&A6,'Purchase-Orders'!$B$3:$B$30,"<"&EDATE(A6,1)) -> 181175 | G6: =SUMIFS('Stock-Issuance'!$H$3:$H$47,'Stock-Issuance'!$B$3:$B$47,">="&A6,'Stock-Issuance'!$B$3:$B$47,"<"&EDATE(A6,1)) -> 13150 | H6: =IFERROR(F6/E6,0) -> 30195.833
A7: 46143 | B7: =COUNTIFS('Procurement-Requests'!$B$3:$B$32,">="&A7,'Procurement-Requests'!$B$3:$B$32,"<"&EDATE(A7,1)) -> 5 | C7: =COUNTIFS('Procurement-Requests'!$B$3:$B$32,">="&A7,'Procurement-Requests'!$B$3:$B$32,"<"&EDATE(A7,1),'Procurement-Requests'!$I$3:$I$32,"Approved")+COUNTIFS('Procurement-Requests'!$B$3:$B$32,">="&A7,'Procurement-Requests'!$B$3:$B$32,"<"&EDATE(A7,1),'Procurement-Requests'!$I$3:$I$32,"Fulfilled") -> 3 | D7: =COUNTIFS('Procurement-Requests'!$B$3:$B$32,">="&A7,'Procurement-Requests'!$B$3:$B$32,"<"&EDATE(A7,1),'Procurement-Requests'!$I$3:$I$32,"Pending") -> 2 | E7: =COUNTIFS('Purchase-Orders'!$B$3:$B$30,">="&A7,'Purchase-Orders'!$B$3:$B$30,"<"&EDATE(A7,1)) -> 4 | F7: =SUMIFS('Purchase-Orders'!$I$3:$I$30,'Purchase-Orders'!$B$3:$B$30,">="&A7,'Purchase-Orders'!$B$3:$B$30,"<"&EDATE(A7,1)) -> 6375 | G7: =SUMIFS('Stock-Issuance'!$H$3:$H$47,'Stock-Issuance'!$B$3:$B$47,">="&A7,'Stock-Issuance'!$B$3:$B$47,"<"&EDATE(A7,1)) -> 22980 | H7: =IFERROR(F7/E7,0) -> 1593.75
A8: 46174 | B8: =COUNTIFS('Procurement-Requests'!$B$3:$B$32,">="&A8,'Procurement-Requests'!$B$3:$B$32,"<"&EDATE(A8,1)) -> 5 | C8: =COUNTIFS('Procurement-Requests'!$B$3:$B$32,">="&A8,'Procurement-Requests'!$B$3:$B$32,"<"&EDATE(A8,1),'Procurement-Requests'!$I$3:$I$32,"Approved")+COUNTIFS('Procurement-Requests'!$B$3:$B$32,">="&A8,'Procurement-Requests'!$B$3:$B$32,"<"&EDATE(A8,1),'Procurement-Requests'!$I$3:$I$32,"Fulfilled") -> 4 | D8: =COUNTIFS('Procurement-Requests'!$B$3:$B$32,">="&A8,'Procurement-Requests'!$B$3:$B$32,"<"&EDATE(A8,1),'Procurement-Requests'!$I$3:$I$32,"Pending") -> 1 | E8: =COUNTIFS('Purchase-Orders'!$B$3:$B$30,">="&A8,'Purchase-Orders'!$B$3:$B$30,"<"&EDATE(A8,1)) -> 5 | F8: =SUMIFS('Purchase-Orders'!$I$3:$I$30,'Purchase-Orders'!$B$3:$B$30,">="&A8,'Purchase-Orders'!$B$3:$B$30,"<"&EDATE(A8,1)) -> 5950 | G8: =SUMIFS('Stock-Issuance'!$H$3:$H$47,'Stock-Issuance'!$B$3:$B$47,">="&A8,'Stock-Issuance'!$B$3:$B$47,"<"&EDATE(A8,1)) -> 7965 | H8: =IFERROR(F8/E8,0) -> 1190
A9: Total | B9: =SUM(B3:B8) -> 30 | C9: =SUM(C3:C8) -> 20 | D9: =SUM(D3:D8) -> 8 | E9: =SUM(E3:E8) -> 28 | F9: =SUM(F3:F8) -> 250365 | G9: =SUM(G3:G8) -> 88214 | H9: =IFERROR(F9/E9,0) -> 8941.6071

Sheet Settings
A1: System Settings & Lookup Lists
A3: Categories | B3: Units | C3: Departments | D3: Request Status | E3: PO Status | F3: Priority | G3: Supplier Status | H3: Movement Type
A4: Paper Products | B4: Ream | C4: Admin | D4: Pending | E4: Pending | F4: Low | G4: Active | H4: Issuance
A5: Writing Instruments | B5: Box | C5: Finance | D5: Approved | E5: Ordered | F5: Medium | G5: Inactive | H5: Return
A6: Office Equipment | B6: Piece | C6: HR | D6: Rejected | E6: Partially Delivered | F6: High | H6: Adjustment
A7: Filing & Storage | B7: Pack | C7: IT | D7: Fulfilled | E7: Delivered | F7: Urgent | H7: Receiving
A8: Stationery | B8: Roll | C8: Marketing | E8: Cancelled
A9: Printing Supplies | C9: Operations
A10: IT Accessories | C10: Procurement
A11: Packaging Materials | C11: Sales
