Workbook
Name CategoryList: #REF!
Name DepartmentList: #REF!
Name ItemCategoryLookup: 'Inventory-Master'!$B$3:$C$32
Name ItemFullTable: 'Inventory-Master'!$A$3:$L$32
Name ItemList: 'Inventory-Master'!$B$3:$B$32
Name MovementTypeList: #REF!
Name POStatusList: #REF!
Name PriorityList: #REF!
Name ReqStatusList: #REF!
Name SupplierList: #REF!
Name SupplierStatusList: #REF!
Name UnitList: #REF!

Sheet Dashboard
A1: Sample Office Supply Inventory Monitoring System
N2: Chart Support Data (auto-calculated — do not delete)
N3: Paper Products | O3: =SUMIF('Inventory-Master'!$C$3:$C$32,N3,'Inventory-Master'!$H$3:$H$32) -> 5800
A4: TOTAL ITEMS | C4: INVENTORY VALUE | E4: LOW STOCK ITEMS | N4: Writing Instruments | O4: =SUMIF('Inventory-Master'!$C$3:$C$32,N4,'Inventory-Master'!$H$3:$H$32) -> 8355
A5: =COUNTA('Inventory-Master'!B3:B32) -> 30 | C5: =SUM('Inventory-Master'!H3:H32) -> 74930 | E5: =COUNTIF('Inventory-Master'!J3:J32,"Low Stock") -> 4 | N5: Office Equipment | O5: =SUMIF('Inventory-Master'!$C$3:$C$32,N5,'Inventory-Master'!$H$3:$H$32) -> 14750
N6: Filing & Storage | O6: =SUMIF('Inventory-Master'!$C$3:$C$32,N6,'Inventory-Master'!$H$3:$H$32) -> 17300 | P6: =IF('Inventory-Master'!J7="Low Stock",ROW('Inventory-Master'!J7),"")
H7: Office Supply Issuance by Department | N7: Stationery | O7: =SUMIF('Inventory-Master'!$C$3:$C$32,N7,'Inventory-Master'!$H$3:$H$32) -> 1425 | P7: =IF('Inventory-Master'!J8="Low Stock",ROW('Inventory-Master'!J8),"")
N8: Printing Supplies | O8: =SUMIF('Inventory-Master'!$C$3:$C$32,N8,'Inventory-Master'!$H$3:$H$32) -> 18500 | P8: =IF('Inventory-Master'!J9="Low Stock",ROW('Inventory-Master'!J9),"")
A9: Category | B9: Inventory Table | H9: Department | I9: Sum of Quantity Issued | J9: Sum of Total Value | N9: =IF('Inventory-Master'!J10="Low Stock",ROW('Inventory-Master'!J10),"")
A10: Writing Instruments | B10: =SUMIF('Inventory-Master'!C2:C32,A10,'Inventory-Master'!H3:H32) -> 7855 | H10: Admin | I10: 41 | J10: 18225 | N10: =IF('Inventory-Master'!J11="Low Stock",ROW('Inventory-Master'!J11),"")
A11: Office Equipment | B11: =SUMIF('Inventory-Master'!C3:C33,A11,'Inventory-Master'!H4:H33) -> 13650 | H11: Finance | I11: 78 | J11: 25670 | N11: =IF('Inventory-Master'!J12="Low Stock",ROW('Inventory-Master'!J12),"")
A12: Filing & Storage | B12: =SUMIF('Inventory-Master'!C4:C34,A12,'Inventory-Master'!H5:H34) -> 18000 | H12: HR | I12: 20 | J12: 1450 | N12: =IF('Inventory-Master'!J13="Low Stock",ROW('Inventory-Master'!J13),"")
A13: Paper Products | B13: =SUMIF('Inventory-Master'!C5:C35,A13,'Inventory-Master'!H6:H35) -> 1050 | H13: IT | I13: 76 | J13: 6375 | N13: =IF('Inventory-Master'!J14="Low Stock",ROW('Inventory-Master'!J14),"")
A14: Stationery | B14: =SUMIF('Inventory-Master'!C6:C36,A14,'Inventory-Master'!H7:H36) -> 1175 | H14: Marketing | I14: 50 | J14: 3515 | N14: =IF('Inventory-Master'!J15="Low Stock",ROW('Inventory-Master'!J15),"")
A15: Printing Supplies | B15: =SUMIF('Inventory-Master'!C7:C37,A15,'Inventory-Master'!H8:H37) -> 23700 | H15: Operations | I15: 96 | J15: 12615 | N15: =IF('Inventory-Master'!J16="Low Stock",ROW('Inventory-Master'!J16),"")
A16: IT Accessories | B16: =SUMIF('Inventory-Master'!C8:C38,A16,'Inventory-Master'!H9:H38) -> 1000 | H16: Procurement | I16: 44 | J16: 13005 | N16: =IF('Inventory-Master'!J17="Low Stock",ROW('Inventory-Master'!J17),"")
A17: Packaging Materials | B17: =SUMIF('Inventory-Master'!C9:C39,A17,'Inventory-Master'!H10:H39) -> 5800 | H17: Sales | I17: 32 | J17: 7359 | N17: =IF('Inventory-Master'!J18="Low Stock",ROW('Inventory-Master'!J18),"")
H18: Grand Total | I18: 437 | J18: 88214 | P18: =IF('Inventory-Master'!J19="Low Stock",ROW('Inventory-Master'!J19),"")
N19: Department | O19: Requests | P19: =IF('Inventory-Master'!J20="Low Stock",ROW('Inventory-Master'!J20),"")
N20: Admin | O20: =COUNTIF(#REF!,N20) -> #REF! | P20: =IF('Inventory-Master'!J21="Low Stock",ROW('Inventory-Master'!J21),"")
N21: Finance | O21: =COUNTIF(#REF!,N21) -> #REF! | P21: =IF('Inventory-Master'!J22="Low Stock",ROW('Inventory-Master'!J22),"")
N22: HR | O22: =COUNTIF(#REF!,N22) -> #REF!
N23: IT | O23: =COUNTIF(#REF!,N23) -> #REF! | P23: =IF('Inventory-Master'!J24="Low Stock",ROW('Inventory-Master'!J24),"")
N24: Marketing | O24: =COUNTIF(#REF!,N24) -> #REF! | P24: =IF('Inventory-Master'!J25="Low Stock",ROW('Inventory-Master'!J25),"")
N25: =IF('Inventory-Master'!J26="Low Stock",ROW('Inventory-Master'!J26),"")
A26: Low Stock Alert — Items Requiring Immediate Reorder | N26: =IF('Inventory-Master'!J27="Low Stock",ROW('Inventory-Master'!J27),"")
A27: Item ID | B27: Item Name | C27: Category | D27: Current Stock | E27: Reorder Level | F27: Suggested Reorder Qty
A28: =IFERROR(INDEX('Inventory-Master'!$A:$A,IFERROR(SMALL($A$40:$A$43,1),"")),"") -> ITM-003 | B28: =IFERROR(INDEX('Inventory-Master'!$B:$B,IFERROR(SMALL($A$40:$A$43,1),"")),"") -> Stapler | C28: =IFERROR(INDEX('Inventory-Master'!$C:$C,IFERROR(SMALL($A$40:$A$43,1),"")),"") -> Office Equipment | D28: =IFERROR(INDEX('Inventory-Master'!$F:$F,IFERROR(SMALL($A$40:$A$43,1),"")),"") -> 30 | E28: =IFERROR(INDEX('Inventory-Master'!$E:$E,IFERROR(SMALL($A$40:$A$43,1),"")),"") -> 30 | F28: =IFERROR(INDEX('Inventory-Master'!$I:$I,IFERROR(SMALL($A$40:$A$43,1),"")),"") -> 30 | N28: =IF('Inventory-Master'!J29="Low Stock",ROW('Inventory-Master'!J29),"")
A29: =IFERROR(INDEX('Inventory-Master'!$A:$A,IFERROR(SMALL($A$40:$A$43,2),"")),"") -> ITM-021 | B29: =IFERROR(INDEX('Inventory-Master'!$B:$B,IFERROR(SMALL($A$40:$A$43,2),"")),"") -> Desk Calendar | C29: =IFERROR(INDEX('Inventory-Master'!$C:$C,IFERROR(SMALL($A$40:$A$43,2),"")),"") -> Stationery | D29: =IFERROR(INDEX('Inventory-Master'!$F:$F,IFERROR(SMALL($A$40:$A$43,2),"")),"") -> 15 | E29: =IFERROR(INDEX('Inventory-Master'!$E:$E,IFERROR(SMALL($A$40:$A$43,2),"")),"") -> 15 | F29: =IFERROR(INDEX('Inventory-Master'!$I:$I,IFERROR(SMALL($A$40:$A$43,2),"")),"") -> 15 | N29: =IF('Inventory-Master'!J30="Low Stock",ROW('Inventory-Master'!J30),"")
A30: =IFERROR(INDEX('Inventory-Master'!$A:$A,IFERROR(SMALL($A$40:$A$43,3),"")),"") -> ITM-026 | B30: =IFERROR(INDEX('Inventory-Master'!$B:$B,IFERROR(SMALL($A$40:$A$43,3),"")),"") -> Toner Cartridge | C30: =IFERROR(INDEX('Inventory-Master'!$C:$C,IFERROR(SMALL($A$40:$A$43,3),"")),"") -> Printing Supplies | D30: =IFERROR(INDEX('Inventory-Master'!$F:$F,IFERROR(SMALL($A$40:$A$43,3),"")),"") -> 5 | E30: =IFERROR(INDEX('Inventory-Master'!$E:$E,IFERROR(SMALL($A$40:$A$43,3),"")),"") -> 5 | F30: =IFERROR(INDEX('Inventory-Master'!$I:$I,IFERROR(SMALL($A$40:$A$43,3),"")),"") -> 5 | N30: =IF('Inventory-Master'!J31="Low Stock",ROW('Inventory-Master'!J31),"")
A31: =IFERROR(INDEX('Inventory-Master'!$A:$A,IFERROR(SMALL($A$40:$A$43,4),"")),"") -> ITM-030 | B31: =IFERROR(INDEX('Inventory-Master'!$B:$B,IFERROR(SMALL($A$40:$A$43,4),"")),"") -> Calculator | C31: =IFERROR(INDEX('Inventory-Master'!$C:$C,IFERROR(SMALL($A$40:$A$43,4),"")),"") -> Office Equipment | D31: =IFERROR(INDEX('Inventory-Master'!$F:$F,IFERROR(SMALL($A$40:$A$43,4),"")),"") -> 10 | E31: =IFERROR(INDEX('Inventory-Master'!$E:$E,IFERROR(SMALL($A$40:$A$43,4),"")),"") -> 10 | F31: =IFERROR(INDEX('Inventory-Master'!$I:$I,IFERROR(SMALL($A$40:$A$43,4),"")),"") -> 10
A32: =IFERROR(INDEX('Inventory-Master'!$A:$A,IFERROR(SMALL($A$40:$A$43,5),"")),"") | B32: =IFERROR(INDEX('Inventory-Master'!$B:$B,IFERROR(SMALL($A$40:$A$43,5),"")),"") | C32: =IFERROR(INDEX('Inventory-Master'!$C:$C,IFERROR(SMALL($A$40:$A$43,5),"")),"") | D32: =IFERROR(INDEX('Inventory-Master'!$F:$F,IFERROR(SMALL($A$40:$A$43,5),"")),"") | E32: =IFERROR(INDEX('Inventory-Master'!$E:$E,IFERROR(SMALL($A$40:$A$43,5),"")),"") | F32: =IFERROR(INDEX('Inventory-Master'!$I:$I,IFERROR(SMALL($A$40:$A$43,5),"")),"")
A33: =IFERROR(INDEX('Inventory-Master'!$A:$A,IFERROR(SMALL($A$40:$A$43,6),"")),"") | B33: =IFERROR(INDEX('Inventory-Master'!$B:$B,IFERROR(SMALL($A$40:$A$43,6),"")),"") | C33: =IFERROR(INDEX('Inventory-Master'!$C:$C,IFERROR(SMALL($A$40:$A$43,6),"")),"") | D33: =IFERROR(INDEX('Inventory-Master'!$F:$F,IFERROR(SMALL($A$40:$A$43,6),"")),"") | E33: =IFERROR(INDEX('Inventory-Master'!$E:$E,IFERROR(SMALL($A$40:$A$43,6),"")),"") | F33: =IFERROR(INDEX('Inventory-Master'!$I:$I,IFERROR(SMALL($A$40:$A$43,6),"")),"")
A34: =IFERROR(INDEX('Inventory-Master'!$A:$A,IFERROR(SMALL($A$40:$A$43,7),"")),"") | B34: =IFERROR(INDEX('Inventory-Master'!$B:$B,IFERROR(SMALL($A$40:$A$43,7),"")),"") | C34: =IFERROR(INDEX('Inventory-Master'!$C:$C,IFERROR(SMALL($A$40:$A$43,7),"")),"") | D34: =IFERROR(INDEX('Inventory-Master'!$F:$F,IFERROR(SMALL($A$40:$A$43,7),"")),"") | E34: =IFERROR(INDEX('Inventory-Master'!$E:$E,IFERROR(SMALL($A$40:$A$43,7),"")),"") | F34: =IFERROR(INDEX('Inventory-Master'!$I:$I,IFERROR(SMALL($A$40:$A$43,7),"")),"")
A35: =IFERROR(INDEX('Inventory-Master'!$A:$A,IFERROR(SMALL($P$3:$P$31,8),"")),"") | B35: =IFERROR(INDEX('Inventory-Master'!$B:$B,IFERROR(SMALL($A$40:$A$43,8),"")),"") | C35: =IFERROR(INDEX('Inventory-Master'!$C:$C,IFERROR(SMALL($A$40:$A$43,8),"")),"") | D35: =IFERROR(INDEX('Inventory-Master'!$F:$F,IFERROR(SMALL($A$40:$A$43,8),"")),"") | E35: =IFERROR(INDEX('Inventory-Master'!$E:$E,IFERROR(SMALL($A$40:$A$43,8),"")),"") | F35: =IFERROR(INDEX('Inventory-Master'!$I:$I,IFERROR(SMALL($A$40:$A$43,8),"")),"")
A36: =IFERROR(INDEX('Inventory-Master'!$A:$A,IFERROR(SMALL($A$40:$A$43,9),"")),"") | B36: =IFERROR(INDEX('Inventory-Master'!$B:$B,IFERROR(SMALL($A$40:$A$43,9),"")),"") | C36: =IFERROR(INDEX('Inventory-Master'!$C:$C,IFERROR(SMALL($A$40:$A$43,9),"")),"") | D36: =IFERROR(INDEX('Inventory-Master'!$F:$F,IFERROR(SMALL($A$40:$A$43,9),"")),"") | E36: =IFERROR(INDEX('Inventory-Master'!$E:$E,IFERROR(SMALL($A$40:$A$43,9),"")),"") | F36: =IFERROR(INDEX('Inventory-Master'!$I:$I,IFERROR(SMALL($A$40:$A$43,9),"")),"")
A37: =IFERROR(INDEX('Inventory-Master'!$A:$A,IFERROR(SMALL($A$40:$A$43,10),"")),"") | B37: =IFERROR(INDEX('Inventory-Master'!$B:$B,IFERROR(SMALL($A$40:$A$43,10),"")),"") | C37: =IFERROR(INDEX('Inventory-Master'!$C:$C,IFERROR(SMALL($A$40:$A$43,10),"")),"") | D37: =IFERROR(INDEX('Inventory-Master'!$F:$F,IFERROR(SMALL($A$40:$A$43,10),"")),"") | E37: =IFERROR(INDEX('Inventory-Master'!$E:$E,IFERROR(SMALL($A$40:$A$43,10),"")),"") | F37: =IFERROR(INDEX('Inventory-Master'!$I:$I,IFERROR(SMALL($A$40:$A$43,10),"")),"")
A39: Low Stock Reference
A40: =IF('Inventory-Master'!J5="Low Stock",ROW('Inventory-Master'!J5),"") -> 5
A41: =IF('Inventory-Master'!J23="Low Stock",ROW('Inventory-Master'!J23),"") -> 23
...

Sheet Inventory-Master
A1: Inventory Master List
A2: Item ID | B2: Item Name | C2: Category | D2: Unit | E2: Reorder Level | F2: Current Stock | G2: Unit Cost | H2: Stock Value | I2: Reorder Qty Suggested | J2: Stock Status | K2: Preferred Supplier | L2: Last Restocked
A3: ITM-001 | B3: Bond Paper A4 | C3: Paper Products | D3: Ream | E3: 5 | F3: 10 | G3: 130 | H3: =F3*G3 -> 1300 | I3: =IF(F3<=E3,(E3*2)-F3,0) -> 0 | J3: =IF(F3<=E3,"Low Stock",IF(F3<=E3*1.5,"Monitor","OK")) -> OK | K3: Prime Paper Solutions | L3: 46086
A4: ITM-002 | B4: Ballpen Black | C4: Writing Instruments | D4: Box | E4: 10 | F4: 20 | G4: 70 | H4: =F4*G4 -> 1400 | I4: =IF(F4<=E4,(E4*2)-F4,0) -> 0 | J4: =IF(F4<=E4,"Low Stock",IF(F4<=E4*1.5,"Monitor","OK")) -> OK | K4: Signature Pens & More | L4: 46133
A5: ITM-003 | B5: Stapler | C5: Office Equipment | D5: Piece | E5: 30 | F5: 30 | G5: 35 | H5: =F5*G5 -> 1050 | I5: =IF(F5<=E5,(E5*2)-F5,0) -> 30 | J5: =IF(F5<=E5,"Low Stock",IF(F5<=E5*1.5,"Monitor","OK")) -> Low Stock | K5: Office Essentials Trading | L5: 46025
A6: ITM-004 | B6: Staple Wire | C6: Office Equipment | D6: Box | E6: 30 | F6: 90 | G6: 40 | H6: =F6*G6 -> 3600 | I6: =IF(F6<=E6,(E6*2)-F6,0) -> 0 | J6: =IF(F6<=E6,"Low Stock",IF(F6<=E6*1.5,"Monitor","OK")) -> OK | K6: Office Essentials Trading | L6: 46146
A7: ITM-005 | B7: Pencil HB | C7: Writing Instruments | D7: Box | E7: 5 | F7: 15 | G7: 100 | H7: =F7*G7 -> 1500 | I7: =IF(F7<=E7,(E7*2)-F7,0) -> 0 | J7: =IF(F7<=E7,"Low Stock",IF(F7<=E7*1.5,"Monitor","OK")) -> OK | K7: Signature Pens & More | L7: 46100
A8: ITM-006 | B8: Eraser | C8: Writing Instruments | D8: Box | E8: 10 | F8: 20 | G8: 50 | H8: =F8*G8 -> 1000 | I8: =IF(F8<=E8,(E8*2)-F8,0) -> 0 | J8: =IF(F8<=E8,"Low Stock",IF(F8<=E8*1.5,"Monitor","OK")) -> OK | K8: Signature Pens & More | L8: 46039
A9: ITM-007 | B9: Highlighter Yellow | C9: Writing Instruments | D9: Piece | E9: 30 | F9: 60 | G9: 48 | H9: =F9*G9 -> 2880 | I9: =IF(F9<=E9,(E9*2)-F9,0) -> 0 | J9: =IF(F9<=E9,"Low Stock",IF(F9<=E9*1.5,"Monitor","OK")) -> OK | K9: Signature Pens & More | L9: 46055
A10: ITM-008 | B10: Permanent Marker Black | C10: Writing Instruments | D10: Piece | E10: 30 | F10: 50 | G10: 15 | H10: =F10*G10 -> 750 | I10: =IF(F10<=E10,(E10*2)-F10,0) -> 0 | J10: =IF(F10<=E10,"Low Stock",IF(F10<=E10*1.5,"Monitor","OK")) -> OK | K10: Signature Pens & More | L10: 46036
A11: ITM-009 | B11: Whiteboard Marker Blue | C11: Writing Instruments | D11: Piece | E11: 30 | F11: 55 | G11: 15 | H11: =F11*G11 -> 825 | I11: =IF(F11<=E11,(E11*2)-F11,0) -> 0 | J11: =IF(F11<=E11,"Low Stock",IF(F11<=E11*1.5,"Monitor","OK")) -> OK | K11: Signature Pens & More | L11: 46115
A12: ITM-010 | B12: Correction Tape | C12: Office Equipment | D12: Piece | E12: 30 | F12: 90 | G12: 15 | H12: =F12*G12 -> 1350 | I12: =IF(F12<=E12,(E12*2)-F12,0) -> 0 | J12: =IF(F12<=E12,"Low Stock",IF(F12<=E12*1.5,"Monitor","OK")) -> OK | K12: Office Essentials Trading | L12: 46056
A13: ITM-011 | B13: Glue Stick | C13: Office Equipment | D13: Pack | E13: 5 | F13: 15 | G13: 45 | H13: =F13*G13 -> 675 | I13: =IF(F13<=E13,(E13*2)-F13,0) -> 0 | J13: =IF(F13<=E13,"Low Stock",IF(F13<=E13*1.5,"Monitor","OK")) -> OK | K13: Office Essentials Trading | L13: 46156
A14: ITM-012 | B14: Scissors | C14: Office Equipment | D14: Piece | E14: 30 | F14: 40 | G14: 10 | H14: =F14*G14 -> 400 | I14: =IF(F14<=E14,(E14*2)-F14,0) -> 0 | J14: =IF(F14<=E14,"Low Stock",IF(F14<=E14*1.5,"Monitor","OK")) -> Monitor | K14: Office Essentials Trading | L14: 46049
... A32: ITM-030 | B32: Calculator | C32: Office Equipment | D32: Piece | E32: 10 | F32: 10 | G32: 400 | H32: =F32*G32 -> 4000 | I32: =IF(F32<=E32,(E32*2)-F32,0) -> 10 | J32: =IF(F32<=E32,"Low Stock",IF(F32<=E32*1.5,"Monitor","OK")) -> Low Stock | K32: Office Essentials Trading | L32: 46176

Sheet Stock-Issuance
A1: Stock Issuance Log
A2: Issuance ID | B2: Date | C2: Item | D2: Category | E2: Department | F2: Quantity Issued | G2: Unit Cost | H2: Total Value | I2: Issued By | J2: Purpose / Remarks
A3: ISS-0001 | B3: 46030 | C3: Bond Paper A4 | D3: =IFERROR(INDEX('Inventory-Master'!$C$3:$C$32,MATCH(C3,'Inventory-Master'!$B$3:$B$32,0)),"") -> Paper Products | E3: IT | F3: 15 | G3: =IFERROR(INDEX('Inventory-Master'!$G$3:$G$32,MATCH(C3,'Inventory-Master'!$B$3:$B$32,0)),0) -> 130 | H3: =F3*G3 -> 1950 | I3: Lorna Pascual | J3: Event/meeting preparation
A4: ISS-0002 | B4: 46081 | C4: Stapler | D4: =IFERROR(INDEX('Inventory-Master'!$C$3:$C$32,MATCH(C4,'Inventory-Master'!$B$3:$B$32,0)),"") -> Office Equipment | E4: Marketing | F4: 10 | G4: =IFERROR(INDEX('Inventory-Master'!$G$3:$G$32,MATCH(C4,'Inventory-Master'!$B$3:$B$32,0)),0) -> 35 | H4: =F4*G4 -> 350 | I4: Jun Bautista | J4: Replacement of damaged item
A5: ISS-0003 | B5: 46094 | C5: Printer Ink Black | D5: =IFERROR(INDEX('Inventory-Master'!$C$3:$C$32,MATCH(C5,'Inventory-Master'!$B$3:$B$32,0)),"") -> Printing Supplies | E5: Operations | F5: 1 | G5: =IFERROR(INDEX('Inventory-Master'!$G$3:$G$32,MATCH(C5,'Inventory-Master'!$B$3:$B$32,0)),0) -> 100 | H5: =F5*G5 -> 100 | I5: Ferdie Aguilar | J5: Event/meeting preparation
A6: ISS-0004 | B6: 46118 | C6: Notebook A5 | D6: =IFERROR(INDEX('Inventory-Master'!$C$3:$C$32,MATCH(C6,'Inventory-Master'!$B$3:$B$32,0)),"") -> Paper Products | E6: Marketing | F6: 1 | G6: =IFERROR(INDEX('Inventory-Master'!$G$3:$G$32,MATCH(C6,'Inventory-Master'!$B$3:$B$32,0)),0) -> 150 | H6: =F6*G6 -> 150 | I6: Ferdie Aguilar | J6: Replacement of damaged item
A7: ISS-0005 | B7: 46156 | C7: Scissors | D7: =IFERROR(INDEX('Inventory-Master'!$C$3:$C$32,MATCH(C7,'Inventory-Master'!$B$3:$B$32,0)),"") -> Office Equipment | E7: Operations | F7: 15 | G7: =IFERROR(INDEX('Inventory-Master'!$G$3:$G$32,MATCH(C7,'Inventory-Master'!$B$3:$B$32,0)),0) -> 10 | H7: =F7*G7 -> 150 | I7: Jun Bautista | J7: Replacement of damaged item
A8: ISS-0006 | B8: 46177 | C8: Paper Clips | D8: =IFERROR(INDEX('Inventory-Master'!$C$3:$C$32,MATCH(C8,'Inventory-Master'!$B$3:$B$32,0)),"") -> Office Equipment | E8: IT | F8: 8 | G8: =IFERROR(INDEX('Inventory-Master'!$G$3:$G$32,MATCH(C8,'Inventory-Master'!$B$3:$B$32,0)),0) -> 35 | H8: =F8*G8 -> 280 | I8: Ferdie Aguilar | J8: Project-specific requirement
A9: ISS-0007 | B9: 46036 | C9: Bond Paper A4 | D9: =IFERROR(INDEX('Inventory-Master'!$C$3:$C$32,MATCH(C9,'Inventory-Master'!$B$3:$B$32,0)),"") -> Paper Products | E9: IT | F9: 10 | G9: =IFERROR(INDEX('Inventory-Master'!$G$3:$G$32,MATCH(C9,'Inventory-Master'!$B$3:$B$32,0)),0) -> 130 | H9: =F9*G9 -> 1300 | I9: Lorna Pascual | J9: Routine department replenishment
A10: ISS-0008 | B10: 46075 | C10: Calculator | D10: =IFERROR(INDEX('Inventory-Master'!$C$3:$C$32,MATCH(C10,'Inventory-Master'!$B$3:$B$32,0)),"") -> Office Equipment | E10: Operations | F10: 10 | G10: =IFERROR(INDEX('Inventory-Master'!$G$3:$G$32,MATCH(C10,'Inventory-Master'!$B$3:$B$32,0)),0) -> 400 | H10: =F10*G10 -> 4000 | I10: Jun Bautista | J10: Routine department replenishment
A11: ISS-0009 | B11: 46105 | C11: Packaging Tape | D11: =IFERROR(INDEX('Inventory-Master'!$C$3:$C$32,MATCH(C11,'Inventory-Master'!$B$3:$B$32,0)),"") -> Packaging Materials | E11: Marketing | F11: 8 | G11: =IFERROR(INDEX('Inventory-Master'!$G$3:$G$32,MATCH(C11,'Inventory-Master'!$B$3:$B$32,0)),0) -> 40 | H11: =F11*G11 -> 320 | I11: Jun Bautista | J11: Monthly office supply allocation
A12: ISS-0010 | B12: 46123 | C12: Paper Clips | D12: =IFERROR(INDEX('Inventory-Master'!$C$3:$C$32,MATCH(C12,'Inventory-Master'!$B$3:$B$32,0)),"") -> Office Equipment | E12: Marketing | F12: 3 | G12: =IFERROR(INDEX('Inventory-Master'!$G$3:$G$32,MATCH(C12,'Inventory-Master'!$B$3:$B$32,0)),0) -> 35 | H12: =F12*G12 -> 105 | I12: Ferdie Aguilar | J12: Monthly office supply allocation
A13: ISS-0011 | B13: 46164 | C13: Paper Clips | D13: =IFERROR(INDEX('Inventory-Master'!$C$3:$C$32,MATCH(C13,'Inventory-Master'!$B$3:$B$32,0)),"") -> Office Equipment | E13: HR | F13: 8 | G13: =IFERROR(INDEX('Inventory-Master'!$G$3:$G$32,MATCH(C13,'Inventory-Master'!$B$3:$B$32,0)),0) -> 35 | H13: =F13*G13 -> 280 | I13: Lorna Pascual | J13: Replacement of damaged item
A14: ISS-0012 | B14: 46200 | C14: Bond Paper A4 | D14: =IFERROR(INDEX('Inventory-Master'!$C$3:$C$32,MATCH(C14,'Inventory-Master'!$B$3:$B$32,0)),"") -> Paper Products | E14: Marketing | F14: 8 | G14: =IFERROR(INDEX('Inventory-Master'!$G$3:$G$32,MATCH(C14,'Inventory-Master'!$B$3:$B$32,0)),0) -> 130 | H14: =F14*G14 -> 1040 | I14: Ferdie Aguilar | J14: Monthly office supply allocation
... A47: ISS-0045 | B47: 46085 | C47: Notebook A5 | D47: =IFERROR(INDEX('Inventory-Master'!$C$3:$C$32,MATCH(C47,'Inventory-Master'!$B$3:$B$32,0)),"") -> Paper Products | E47: Admin | F47: 8 | G47: =IFERROR(INDEX('Inventory-Master'!$G$3:$G$32,MATCH(C47,'Inventory-Master'!$B$3:$B$32,0)),0) -> 150 | H47: =F47*G47 -> 1200 | I47: Jun Bautista | J47: Project-specific requirement
